Workbook

Sheet Camera (NINA)
A1: Camera | B1: Id | C1: Year | D1: Processor | F1: Sensor | Q1: CropSubSampling | AQ1: ="{"&_xlfn.TEXTJOIN(", ",TRUE,AQ4:AQ60)&"}" -> #VALUE!
F2: Name | G2: Type | H2: Bayer | I2: BitDepth | J2: ResX | K2: ResY | L2: SizeX | M2: SizeY | N2: PixelSizeX | O2: PixelSizeY | Q2: Id | R2: FX | S2: FX | T2: FX | U2: DX | V2: DX | W2: DX | X2: 1inch | Y2: 1inch | Z2: 1inch | AA2: 1.3x | AB2: 1.3x | AC2: 1.3x | AD2: 5:4 | AE2: 5:4 | AF2: 5:4 | AG2: 1.2x | AH2: 1.2x | AI2: 1.2x | AJ2: 1:1 | AK2: 1:1 | AL2: 1:1 | AM2: 16:9 | AN2: 16:9 | AO2: 16:9
R3: Size L | S3: Size M | T3: Size S | U3: Size L | V3: Size M | W3: Size S | X3: Size L | Y3: Size M | Z3: Size S | AA3: Size L | AB3: Size M | AC3: Size S | AD3: Size L | AE3: Size M | AF3: Size S | AG3: Size L | AH3: Size M | AI3: Size S | AJ3: Size L | AK3: Size M | AL3: Size S | AM3: Size L | AN3: Size M | AO3: Size S
A4: D3 | B4: D3 | C4: 2007 | D4: EXPEED | F4: Nikon NC81338L | G4: CMOS | I4: 14 | J4: 4256 | K4: 2832 | L4: 36 | M4: 23.9 | N4: 8.43 | O4: 8.43 | Q4: FX 0, DX 1, 5:4 2 | R4: 4256x2832 | S4: 3184x2120 | T4: 2128x1416 | U4: 2784x1848 | V4: 2080x1384 | W4: 1392x920 | AD4: 3552x2832 | AE4: 2656x2120 | AF4: 1776x1416 | AQ4: =""""&B4&""": {"&"""Name"": "&""""&A4&""", "&"""Year"": "&C4&", "&"""Processor"": "&""""&D4&""", "&"""Sensor"": {"&"""Name"": "&""""&F4&""", "&"""Type"": "&""""&G4&""", "&"""Bayer"": "&""""&H4&""", "&"""BitDepth"": "&""&I4&", "&"""ResX"": "&""&J4&", "&"""ResY"": "&""&K4&", "&"""SizeX"": "&""&SUBSTITUTE(L4,",",".")&", "&"""SizeY"": "&""&SUBSTITUTE(M4,",",".")&", "&"""PixelSizeX"": "&""&SUBSTITUTE(N4,",",".")&", "&"""PixelSizeY"": "&""&SUBSTITUTE(O4,",",".")&"}, "&AR4&"}" -> "D3": {"Name": "D3", "Year": 2007, "Processor": "EXPEED", "Sensor": {"Name": "Nikon NC81338L", "Type": "CMOS", "Bayer": "", "BitDepth": 14, "ResX": 4256, "ResY": 2832, "SizeX": 36, "SizeY": 23.9, "PixelSizeX": 8.43, "PixelSizeY": 8.43}, "CropSubSampling": [{"Crop": "FX", "Subs": {"Size L": {"ResX": 4256, "ResY": 2832}, "Size M": {"ResX": 3184, "ResY": 2120}, "Size S": {"ResX": 2128, "ResY": 1416}}}, {"Crop": "DX", "Subs": {"Size L": {"ResX": 2784, "ResY": 1848}, "Size M": {"ResX": 2080, "ResY": 1384}, "Size S": {"ResX": 1392, "ResY": 920}}}, {"Crop": "5:4", "Subs": {"Size L": {"ResX": 3552, "ResY": 2832}, "Size M": {"ResX": 2656, "ResY": 2120}, "Size S": {"ResX": 1776, "ResY": 1416}}}]} | AR4: {=_xlfn.LET(_xlpm.crop,$R$2:$AO$2,_xlpm.size,$R$3:$AO$3,_xlpm.value,R4:AO4,_xlpm.vf,_xlfn.MAP(_xlpm.size,_xlpm.value,_xlfn.LAMBDA(_xlpm.s,_xlpm.v,IF(_xlpm.v="","",""""&_xlpm.s&""": {""ResX"": "&_xlfn.TEXTBEFORE(_xlpm.v,"x")&", ""ResY"": "&_xlfn.TEXTAFTER(_xlpm.v,"x")&"}"))),_xlpm.vfc,_xlfn.GROUPBY(TRANSPOSE(_xlpm.crop),TRANSPOSE(_xlpm.vf),_xlfn.LAMBDA(_xlpm.v,_xlfn.TEXTJOIN(", ",TRUE,_xlpm.v)),0,0),_xlpm.vfcc,_xlfn.BYROW(_xlpm.vfc,_xlfn.LAMBDA(_xlpm.r,IF(INDEX(_xlpm.r,1,2)="","","{""Crop"": """&INDEX(_xlpm.r,1,1)&""", ""Subs"": {"&INDEX(_xlpm.r,1,2)&"}}"))),_xlpm.vs,_xlfn.SORTBY(_xlpm.vfcc,MATCH(INDEX(_xlpm.vfc,0,1),_xlpm.crop,0)),"""CropSubSampling"": ["&_xlfn.TEXTJOIN(", ",TRUE,_xlpm.vs)&"]")} -> "CropSubSampling": [{"Crop": "FX", "Subs": {"Size L": {"ResX": 4256, "ResY": 2832}, "Size M": {"ResX": 3184, "ResY": 2120}, "Size S": {"ResX": 2128, "ResY": 1416}}}, {"Crop": "DX", "Subs": {"Size L": {"ResX": 2784, "ResY": 1848}, "Size M": {"ResX": 2080, "ResY": 1384}, "Size S": {"ResX": 1392, "ResY": 920}}}, {"Crop": "5:4", "Subs": {"Size L": {"ResX": 3552, "ResY": 2832}, "Size M": {"ResX": 2656, "ResY": 2120}, "Size S": {"ResX": 1776, "ResY": 1416}}}]
A5: D3X | B5: D3X | C5: 2008 | D5: EXPEED | F5: Sony IMX-028 | G5: CMOS | I5: 14 | J5: 6048 | K5: 4032 | L5: 35.9 | M5: 24 | N5: 5.95 | O5: 5.95 | Q5: FX 0, DX 1, 5:4 2 | R5: 6048x4032 | S5: 4544x3024 | T5: 3024x2016 | U5: 3968x2640 | V5: 2976x1976 | W5: 1984x1320 | AD5: 5056x4032 | AE5: 3792x3024 | AF5: 2528x2016 | AQ5: =""""&B5&""": {"&"""Name"": "&""""&A5&""", "&"""Year"": "&C5&", "&"""Processor"": "&""""&D5&""", "&"""Sensor"": {"&"""Name"": "&""""&F5&""", "&"""Type"": "&""""&G5&""", "&"""Bayer"": "&""""&H5&""", "&"""BitDepth"": "&""&I5&", "&"""ResX"": "&""&J5&", "&"""ResY"": "&""&K5&", "&"""SizeX"": "&""&SUBSTITUTE(L5,",",".")&", "&"""SizeY"": "&""&SUBSTITUTE(M5,",",".")&", "&"""PixelSizeX"": "&""&SUBSTITUTE(N5,",",".")&", "&"""PixelSizeY"": "&""&SUBSTITUTE(O5,",",".")&"}, "&AR5&"}" -> "D3X": {"Name": "D3X", "Year": 2008, "Processor": "EXPEED", "Sensor": {"Name": "Sony IMX-028", "Type": "CMOS", "Bayer": "", "BitDepth": 14, "ResX": 6048, "ResY": 4032, "SizeX": 35.9, "SizeY": 24, "PixelSizeX": 5.95, "PixelSizeY": 5.95}, "CropSubSampling": [{"Crop": "FX", "Subs": {"Size L": {"ResX": 6048, "ResY": 4032}, "Size M": {"ResX": 4544, "ResY": 3024}, "Size S": {"ResX": 3024, "ResY": 2016}}}, {"Crop": "DX", "Subs": {"Size L": {"ResX": 3968, "ResY": 2640}, "Size M": {"ResX": 2976, "ResY": 1976}, "Size S": {"ResX": 1984, "ResY": 1320}}}, {"Crop": "5:4", "Subs": {"Size L": {"ResX": 5056, "ResY": 4032}, "Size M": {"ResX": 3792, "ResY": 3024}, "Size S": {"ResX": 2528, "ResY": 2016}}}]} | AR5: {=_xlfn.LET(_xlpm.crop,$R$2:$AO$2,_xlpm.size,$R$3:$AO$3,_xlpm.value,R5:AO5,_xlpm.vf,_xlfn.MAP(_xlpm.size,_xlpm.value,_xlfn.LAMBDA(_xlpm.s,_xlpm.v,IF(_xlpm.v="","",""""&_xlpm.s&""": {""ResX"": "&_xlfn.TEXTBEFORE(_xlpm.v,"x")&", ""ResY"": "&_xlfn.TEXTAFTER(_xlpm.v,"x")&"}"))),_xlpm.vfc,_xlfn.GROUPBY(TRANSPOSE(_xlpm.crop),TRANSPOSE(_xlpm.vf),_xlfn.LAMBDA(_xlpm.v,_xlfn.TEXTJOIN(", ",TRUE,_xlpm.v)),0,0),_xlpm.vfcc,_xlfn.BYROW(_xlpm.vfc,_xlfn.LAMBDA(_xlpm.r,IF(INDEX(_xlpm.r,1,2)="","","{""Crop"": """&INDEX(_xlpm.r,1,1)&""", ""Subs"": {"&INDEX(_xlpm.r,1,2)&"}}"))),_xlpm.vs,_xlfn.SORTBY(_xlpm.vfcc,MATCH(INDEX(_xlpm.vfc,0,1),_xlpm.crop,0)),"""CropSubSampling"": ["&_xlfn.TEXTJOIN(", ",TRUE,_xlpm.vs)&"]")} -> "CropSubSampling": [{"Crop": "FX", "Subs": {"Size L": {"ResX": 6048, "ResY": 4032}, "Size M": {"ResX": 4544, "ResY": 3024}, "Size S": {"ResX": 3024, "ResY": 2016}}}, {"Crop": "DX", "Subs": {"Size L": {"ResX": 3968, "ResY": 2640}, "Size M": {"ResX": 2976, "ResY": 1976}, "Size S": {"ResX": 1984, "ResY": 1320}}}, {"Crop": "5:4", "Subs": {"Size L": {"ResX": 5056, "ResY": 4032}, "Size M": {"ResX": 3792, "ResY": 3024}, "Size S": {"ResX": 2528, "ResY": 2016}}}]
A6: D3S | B6: D3S | C6: 2009 | D6: EXPEED | F6: Nikon NC81361A | G6: CMOS | I6: 14 | J6: 4256 | K6: 2832 | L6: 36 | M6: 23.9 | N6: 8.43 | O6: 8.43 | Q6: FX 0, DX 1, 5:4 2 | R6: 4256x2832 | S6: 3184x2120 | T6: 2128x1416 | U6: 2784x1848 | V6: 2080x1384 | W6: 1392x920 | AD6: 3552x2832 | AE6: 2656x2120 | AF6: 1776x1416 | AQ6: =""""&B6&""": {"&"""Name"": "&""""&A6&""", "&"""Year"": "&C6&", "&"""Processor"": "&""""&D6&""", "&"""Sensor"": {"&"""Name"": "&""""&F6&""", "&"""Type"": "&""""&G6&""", "&"""Bayer"": "&""""&H6&""", "&"""BitDepth"": "&""&I6&", "&"""ResX"": "&""&J6&", "&"""ResY"": "&""&K6&", "&"""SizeX"": "&""&SUBSTITUTE(L6,",",".")&", "&"""SizeY"": "&""&SUBSTITUTE(M6,",",".")&", "&"""PixelSizeX"": "&""&SUBSTITUTE(N6,",",".")&", "&"""PixelSizeY"": "&""&SUBSTITUTE(O6,",",".")&"}, "&AR6&"}" -> "D3S": {"Name": "D3S", "Year": 2009, "Processor": "EXPEED", "Sensor": {"Name": "Nikon NC81361A", "Type": "CMOS", "Bayer": "", "BitDepth": 14, "ResX": 4256, "ResY": 2832, "SizeX": 36, "SizeY": 23.9, "PixelSizeX": 8.43, "PixelSizeY": 8.43}, "CropSubSampling": [{"Crop": "FX", "Subs": {"Size L": {"ResX": 4256, "ResY": 2832}, "Size M": {"ResX": 3184, "ResY": 2120}, "Size S": {"ResX": 2128, "ResY": 1416}}}, {"Crop": "DX", "Subs": {"Size L": {"ResX": 2784, "ResY": 1848}, "Size M": {"ResX": 2080, "ResY": 1384}, "Size S": {"ResX": 1392, "ResY": 920}}}, {"Crop": "5:4", "Subs": {"Size L": {"ResX": 3552, "ResY": 2832}, "Size M": {"ResX": 2656, "ResY": 2120}, "Size S": {"ResX": 1776, "ResY": 1416}}}]} | AR6: {=_xlfn.LET(_xlpm.crop,$R$2:$AO$2,_xlpm.size,$R$3:$AO$3,_xlpm.value,R6:AO6,_xlpm.vf,_xlfn.MAP(_xlpm.size,_xlpm.value,_xlfn.LAMBDA(_xlpm.s,_xlpm.v,IF(_xlpm.v="","",""""&_xlpm.s&""": {""ResX"": "&_xlfn.TEXTBEFORE(_xlpm.v,"x")&", ""ResY"": "&_xlfn.TEXTAFTER(_xlpm.v,"x")&"}"))),_xlpm.vfc,_xlfn.GROUPBY(TRANSPOSE(_xlpm.crop),TRANSPOSE(_xlpm.vf),_xlfn.LAMBDA(_xlpm.v,_xlfn.TEXTJOIN(", ",TRUE,_xlpm.v)),0,0),_xlpm.vfcc,_xlfn.BYROW(_xlpm.vfc,_xlfn.LAMBDA(_xlpm.r,IF(INDEX(_xlpm.r,1,2)="","","{""Crop"": """&INDEX(_xlpm.r,1,1)&""", ""Subs"": {"&INDEX(_xlpm.r,1,2)&"}}"))),_xlpm.vs,_xlfn.SORTBY(_xlpm.vfcc,MATCH(INDEX(_xlpm.vfc,0,1),_xlpm.crop,0)),"""CropSubSampling"": ["&_xlfn.TEXTJOIN(", ",TRUE,_xlpm.vs)&"]")} -> "CropSubSampling": [{"Crop": "FX", "Subs": {"Size L": {"ResX": 4256, "ResY": 2832}, "Size M": {"ResX": 3184, "ResY": 2120}, "Size S": {"ResX": 2128, "ResY": 1416}}}, {"Crop": "DX", "Subs": {"Size L": {"ResX": 2784, "ResY": 1848}, "Size M": {"ResX": 2080, "ResY": 1384}, "Size S": {"ResX": 1392, "ResY": 920}}}, {"Crop": "5:4", "Subs": {"Size L": {"ResX": 3552, "ResY": 2832}, "Size M": {"ResX": 2656, "ResY": 2120}, "Size S": {"ResX": 1776, "ResY": 1416}}}]
A7: D4 | B7: D4 | C7: 2012 | D7: EXPEED 3 | F7: Nikon NC81366W | G7: CMOS | I7: 14 | J7: 4928 | K7: 3280 | L7: 36 | M7: 23.9 | N7: 7.29 | O7: 7.29 | Q7: FX 0, DX 1, 5:4 2, 1.2x 3 | R7: 4928x3280 | S7: 3696x2456 | T7: 2464x1640 | U7: 3200x2128 | V7: 2400x1592 | W7: 1600x1064 | AD7: 4096x3280 | AE7: 3072x2456 | AF7: 2048x1640 | AG7: 4096x2720 | AH7: 3072x2040 | AI7: 2048x1360 | AQ7: =""""&B7&""": {"&"""Name"": "&""""&A7&""", "&"""Year"": "&C7&", "&"""Processor"": "&""""&D7&""", "&"""Sensor"": {"&"""Name"": "&""""&F7&""", "&"""Type"": "&""""&G7&""", "&"""Bayer"": "&""""&H7&""", "&"""BitDepth"": "&""&I7&", "&"""ResX"": "&""&J7&", "&"""ResY"": "&""&K7&", "&"""SizeX"": "&""&SUBSTITUTE(L7,",",".")&", "&"""SizeY"": "&""&SUBSTITUTE(M7,",",".")&", "&"""PixelSizeX"": "&""&SUBSTITUTE(N7,",",".")&", "&"""PixelSizeY"": "&""&SUBSTITUTE(O7,",",".")&"}, "&AR7&"}" -> "D4": {"Name": "D4", "Year": 2012, "Processor": "EXPEED 3", "Sensor": {"Name": "Nikon NC81366W", "Type": "CMOS", "Bayer": "", "BitDepth": 14, "ResX": 4928, "ResY": 3280, "SizeX": 36, "SizeY": 23.9, "PixelSizeX": 7.29, "PixelSizeY": 7.29}, "CropSubSampling": [{"Crop": "FX", "Subs": {"Size L": {"ResX": 4928, "ResY": 3280}, "Size M": {"ResX": 3696, "ResY": 2456}, "Size S": {"ResX": 2464, "ResY": 1640}}}, {"Crop": "DX", "Subs": {"Size L": {"ResX": 3200, "ResY": 2128}, "Size M": {"ResX": 2400, "ResY": 1592}, "Size S": {"ResX": 1600, "ResY": 1064}}}, {"Crop": "5:4", "Subs": {"Size L": {"ResX": 4096, "ResY": 3280}, "Size M": {"ResX": 3072, "ResY": 2456}, "Size S": {"ResX": 2048, "ResY": 1640}}}, {"Crop": "1.2x", "Subs": {"Size L": {"ResX": 4096, "ResY": 2720}, "Size M": {"ResX": 3072, "ResY": 2040}, "Size S": {"ResX": 2048, "ResY": 1360}}}]} | AR7: {=_xlfn.LET(_xlpm.crop,$R$2:$AO$2,_xlpm.size,$R$3:$AO$3,_xlpm.value,R7:AO7,_xlpm.vf,_xlfn.MAP(_xlpm.size,_xlpm.value,_xlfn.LAMBDA(_xlpm.s,_xlpm.v,IF(_xlpm.v="","",""""&_xlpm.s&""": {""ResX"": "&_xlfn.TEXTBEFORE(_xlpm.v,"x")&", ""ResY"": "&_xlfn.TEXTAFTER(_xlpm.v,"x")&"}"))),_xlpm.vfc,_xlfn.GROUPBY(TRANSPOSE(_xlpm.crop),TRANSPOSE(_xlpm.vf),_xlfn.LAMBDA(_xlpm.v,_xlfn.TEXTJOIN(", ",TRUE,_xlpm.v)),0,0),_xlpm.vfcc,_xlfn.BYROW(_xlpm.vfc,_xlfn.LAMBDA(_xlpm.r,IF(INDEX(_xlpm.r,1,2)="","","{""Crop"": """&INDEX(_xlpm.r,1,1)&""", ""Subs"": {"&INDEX(_xlpm.r,1,2)&"}}"))),_xlpm.vs,_xlfn.SORTBY(_xlpm.vfcc,MATCH(INDEX(_xlpm.vfc,0,1),_xlpm.crop,0)),"""CropSubSampling"": ["&_xlfn.TEXTJOIN(", ",TRUE,_xlpm.vs)&"]")} -> "CropSubSampling": [{"Crop": "FX", "Subs": {"Size L": {"ResX": 4928, "ResY": 3280}, "Size M": {"ResX": 3696, "ResY": 2456}, "Size S": {"ResX": 2464, "ResY": 1640}}}, {"Crop": "DX", "Subs": {"Size L": {"ResX": 3200, "ResY": 2128}, "Size M": {"ResX": 2400, "ResY": 1592}, "Size S": {"ResX": 1600, "ResY": 1064}}}, {"Crop": "5:4", "Subs": {"Size L": {"ResX": 4096, "ResY": 3280}, "Size M": {"ResX": 3072, "ResY": 2456}, "Size S": {"ResX": 2048, "ResY": 1640}}}, {"Crop": "1.2x", "Subs": {"Size L": {"ResX": 4096, "ResY": 2720}, "Size M": {"ResX": 3072, "ResY": 2040}, "Size S": {"ResX": 2048, "ResY": 1360}}}]
A8: D4S | B8: D4S | C8: 2014 | D8: EXPEED 4 | F8: Nikon NC81366W | G8: CMOS | I8: 14 | J8: 4928 | K8: 3280 | L8: 36 | M8: 23.9 | N8: 7.29 | O8: 7.29 | Q8: FX 0, DX 1, 5:4 2, 1.2x 3 | R8: 4928x3280 | S8: 3696x2456 | T8: 2464x1640 | U8: 3200x2128 | V8: 2400x1592 | W8: 1600x1064 | AD8: 4096x3280 | AE8: 3072x2456 | AF8: 2048x1640 | AG8: 4096x2720 | AH8: 3072x2040 | AI8: 2048x1360 | AQ8: =""""&B8&""": {"&"""Name"": "&""""&A8&""", "&"""Year"": "&C8&", "&"""Processor"": "&""""&D8&""", "&"""Sensor"": {"&"""Name"": "&""""&F8&""", "&"""Type"": "&""""&G8&""", "&"""Bayer"": "&""""&H8&""", "&"""BitDepth"": "&""&I8&", "&"""ResX"": "&""&J8&", "&"""ResY"": "&""&K8&", "&"""SizeX"": "&""&SUBSTITUTE(L8,",",".")&", "&"""SizeY"": "&""&SUBSTITUTE(M8,",",".")&", "&"""PixelSizeX"": "&""&SUBSTITUTE(N8,",",".")&", "&"""PixelSizeY"": "&""&SUBSTITUTE(O8,",",".")&"}, "&AR8&"}" -> "D4S": {"Name": "D4S", "Year": 2014, "Processor": "EXPEED 4", "Sensor": {"Name": "Nikon NC81366W", "Type": "CMOS", "Bayer": "", "BitDepth": 14, "ResX": 4928, "ResY": 3280, "SizeX": 36, "SizeY": 23.9, "PixelSizeX": 7.29, "PixelSizeY": 7.29}, "CropSubSampling": [{"Crop": "FX", "Subs": {"Size L": {"ResX": 4928, "ResY": 3280}, "Size M": {"ResX": 3696, "ResY": 2456}, "Size S": {"ResX": 2464, "ResY": 1640}}}, {"Crop": "DX", "Subs": {"Size L": {"ResX": 3200, "ResY": 2128}, "Size M": {"ResX": 2400, "ResY": 1592}, "Size S": {"ResX": 1600, "ResY": 1064}}}, {"Crop": "5:4", "Subs": {"Size L": {"ResX": 4096, "ResY": 3280}, "Size M": {"ResX": 3072, "ResY": 2456}, "Size S": {"ResX": 2048, "ResY": 1640}}}, {"Crop": "1.2x", "Subs": {"Size L": {"ResX": 4096, "ResY": 2720}, "Size M": {"ResX": 3072, "ResY": 2040}, "Size S": {"ResX": 2048, "ResY": 1360}}}]} | AR8: {=_xlfn.LET(_xlpm.crop,$R$2:$AO$2,_xlpm.size,$R$3:$AO$3,_xlpm.value,R8:AO8,_xlpm.vf,_xlfn.MAP(_xlpm.size,_xlpm.value,_xlfn.LAMBDA(_xlpm.s,_xlpm.v,IF(_xlpm.v="","",""""&_xlpm.s&""": {""ResX"": "&_xlfn.TEXTBEFORE(_xlpm.v,"x")&", ""ResY"": "&_xlfn.TEXTAFTER(_xlpm.v,"x")&"}"))),_xlpm.vfc,_xlfn.GROUPBY(TRANSPOSE(_xlpm.crop),TRANSPOSE(_xlpm.vf),_xlfn.LAMBDA(_xlpm.v,_xlfn.TEXTJOIN(", ",TRUE,_xlpm.v)),0,0),_xlpm.vfcc,_xlfn.BYROW(_xlpm.vfc,_xlfn.LAMBDA(_xlpm.r,IF(INDEX(_xlpm.r,1,2)="","","{""Crop"": """&INDEX(_xlpm.r,1,1)&""", ""Subs"": {"&INDEX(_xlpm.r,1,2)&"}}"))),_xlpm.vs,_xlfn.SORTBY(_xlpm.vfcc,MATCH(INDEX(_xlpm.vfc,0,1),_xlpm.crop,0)),"""CropSubSampling"": ["&_xlfn.TEXTJOIN(", ",TRUE,_xlpm.vs)&"]")} -> "CropSubSampling": [{"Crop": "FX", "Subs": {"Size L": {"ResX": 4928, "ResY": 3280}, "Size M": {"ResX": 3696, "ResY": 2456}, "Size S": {"ResX": 2464, "ResY": 1640}}}, {"Crop": "DX", "Subs": {"Size L": {"ResX": 3200, "ResY": 2128}, "Size M": {"ResX": 2400, "ResY": 1592}, "Size S": {"ResX": 1600, "ResY": 1064}}}, {"Crop": "5:4", "Subs": {"Size L": {"ResX": 4096, "ResY": 3280}, "Size M": {"ResX": 3072, "ResY": 2456}, "Size S": {"ResX": 2048, "ResY": 1640}}}, {"Crop": "1.2x", "Subs": {"Size L": {"ResX": 4096, "ResY": 2720}, "Size M": {"ResX": 3072, "ResY": 2040}, "Size S": {"ResX": 2048, "ResY": 1360}}}]
A9: D5 | B9: D5 | C9: 2016 | D9: EXPEED 5 | F9: Toshiba (Sony) T4K54 | G9: CMOS | I9: 14 | J9: 5568 | K9: 3712 | L9: 36 | M9: 23.9 | N9: 6.44 | O9: 6.44 | Q9: FX 0, DX 1, 5:4 2, 1.2x 3 | R9: 5568x3712 | S9: 4176x2784 | T9: 2784x1856 | U9: 3648x2432 | V9: 2736x1824 | W9: 1824x1216 | AD9: 4640x3712 | AE9: 3472x2784 | AF9: 2320x1856 | AG9: 4640x3088 | AH9: 3472x2312 | AI9: 2320x1544 | AQ9: =""""&B9&""": {"&"""Name"": "&""""&A9&""", "&"""Year"": "&C9&", "&"""Processor"": "&""""&D9&""", "&"""Sensor"": {"&"""Name"": "&""""&F9&""", "&"""Type"": "&""""&G9&""", "&"""Bayer"": "&""""&H9&""", "&"""BitDepth"": "&""&I9&", "&"""ResX"": "&""&J9&", "&"""ResY"": "&""&K9&", "&"""SizeX"": "&""&SUBSTITUTE(L9,",",".")&", "&"""SizeY"": "&""&SUBSTITUTE(M9,",",".")&", "&"""PixelSizeX"": "&""&SUBSTITUTE(N9,",",".")&", "&"""PixelSizeY"": "&""&SUBSTITUTE(O9,",",".")&"}, "&AR9&"}" -> "D5": {"Name": "D5", "Year": 2016, "Processor": "EXPEED 5", "Sensor": {"Name": "Toshiba (Sony) T4K54", "Type": "CMOS", "Bayer": "", "BitDepth": 14, "ResX": 5568, "ResY": 3712, "SizeX": 36, "SizeY": 23.9, "PixelSizeX": 6.44, "PixelSizeY": 6.44}, "CropSubSampling": [{"Crop": "FX", "Subs": {"Size L": {"ResX": 5568, "ResY": 3712}, "Size M": {"ResX": 4176, "ResY": 2784}, "Size S": {"ResX": 2784, "ResY": 1856}}}, {"Crop": "DX", "Subs": {"Size L": {"ResX": 3648, "ResY": 2432}, "Size M": {"ResX": 2736, "ResY": 1824}, "Size S": {"ResX": 1824, "ResY": 1216}}}, {"Crop": "5:4", "Subs": {"Size L": {"ResX": 4640, "ResY": 3712}, "Size M": {"ResX": 3472, "ResY": 2784}, "Size S": {"ResX": 2320, "ResY": 1856}}}, {"Crop": "1.2x", "Subs": {"Size L": {"ResX": 4640, "ResY": 3088}, "Size M": {"ResX": 3472, "ResY": 2312}, "Size S": {"ResX": 2320, "ResY": 1544}}}]} | AR9: {=_xlfn.LET(_xlpm.crop,$R$2:$AO$2,_xlpm.size,$R$3:$AO$3,_xlpm.value,R9:AO9,_xlpm.vf,_xlfn.MAP(_xlpm.size,_xlpm.value,_xlfn.LAMBDA(_xlpm.s,_xlpm.v,IF(_xlpm.v="","",""""&_xlpm.s&""": {""ResX"": "&_xlfn.TEXTBEFORE(_xlpm.v,"x")&", ""ResY"": "&_xlfn.TEXTAFTER(_xlpm.v,"x")&"}"))),_xlpm.vfc,_xlfn.GROUPBY(TRANSPOSE(_xlpm.crop),TRANSPOSE(_xlpm.vf),_xlfn.LAMBDA(_xlpm.v,_xlfn.TEXTJOIN(", ",TRUE,_xlpm.v)),0,0),_xlpm.vfcc,_xlfn.BYROW(_xlpm.vfc,_xlfn.LAMBDA(_xlpm.r,IF(INDEX(_xlpm.r,1,2)="","","{""Crop"": """&INDEX(_xlpm.r,1,1)&""", ""Subs"": {"&INDEX(_xlpm.r,1,2)&"}}"))),_xlpm.vs,_xlfn.SORTBY(_xlpm.vfcc,MATCH(INDEX(_xlpm.vfc,0,1),_xlpm.crop,0)),"""CropSubSampling"": ["&_xlfn.TEXTJOIN(", ",TRUE,_xlpm.vs)&"]")} -> "CropSubSampling": [{"Crop": "FX", "Subs": {"Size L": {"ResX": 5568, "ResY": 3712}, "Size M": {"ResX": 4176, "ResY": 2784}, "Size S": {"ResX": 2784, "ResY": 1856}}}, {"Crop": "DX", "Subs": {"Size L": {"ResX": 3648, "ResY": 2432}, "Size M": {"ResX": 2736, "ResY": 1824}, "Size S": {"ResX": 1824, "ResY": 1216}}}, {"Crop": "5:4", "Subs": {"Size L": {"ResX": 4640, "ResY": 3712}, "Size M": {"ResX": 3472, "ResY": 2784}, "Size S": {"ResX": 2320, "ResY": 1856}}}, {"Crop": "1.2x", "Subs": {"Size L": {"ResX": 4640, "ResY": 3088}, "Size M": {"ResX": 3472, "ResY": 2312}, "Size S": {"ResX": 2320, "ResY": 1544}}}]
A10: D6 | B10: D6 | C10: 2020 | D10: EXPEED 6 | F10: Toshiba (Sony) T4K54 | G10: CMOS | I10: 14 | J10: 5568 | K10: 3712 | L10: 36 | M10: 23.9 | N10: 6.44 | O10: 6.44 | Q10: FX 0, 1.2x 1, DX 2, 5:4 3, 1:1 4, 16:9 5 | R10: 5568x3712 | S10: 4176x2784 | T10: 2784x1856 | U10: 3648x2432 | V10: 2736x1824 | W10: 1824x1216 | AD10: 4640x3712 | AE10: 3472x2784 | AF10: 2320x1856 | AG10: 4640x3088 | AH10: 3472x2312 | AI10: 2320x1544 | AJ10: 3712x3712 | AK10: 2784x2784 | AL10: 1856x1856 | AM10: 5568x3128 | AN10: 4176x2344 | AO10: 2784x1560 | AQ10: =""""&B10&""": {"&"""Name"": "&""""&A10&""", "&"""Year"": "&C10&", "&"""Processor"": "&""""&D10&""", "&"""Sensor"": {"&"""Name"": "&""""&F10&""", "&"""Type"": "&""""&G10&""", "&"""Bayer"": "&""""&H10&""", "&"""BitDepth"": "&""&I10&", "&"""ResX"": "&""&J10&", "&"""ResY"": "&""&K10&", "&"""SizeX"": "&""&SUBSTITUTE(L10,",",".")&", "&"""SizeY"": "&""&SUBSTITUTE(M10,",",".")&", "&"""PixelSizeX"": "&""&SUBSTITUTE(N10,",",".")&", "&"""PixelSizeY"": "&""&SUBSTITUTE(O10,",",".")&"}, "&AR10&"}" -> "D6": {"Name": "D6", "Year": 2020, "Processor": "EXPEED 6", "Sensor": {"Name": "Toshiba (Sony) T4K54", "Type": "CMOS", "Bayer": "", "BitDepth": 14, "ResX": 5568, "ResY": 3712, "SizeX": 36, "SizeY": 23.9, "PixelSizeX": 6.44, "PixelSizeY": 6.44}, "CropSubSampling": [{"Crop": "FX", "Subs": {"Size L": {"ResX": 5568, "ResY": 3712}, "Size M": {"ResX": 4176, "ResY": 2784}, "Size S": {"ResX": 2784, "ResY": 1856}}}, {"Crop": "DX", "Subs": {"Size L": {"ResX": 3648, "ResY": 2432}, "Size M": {"ResX": 2736, "ResY": 1824}, "Size S": {"ResX": 1824, "ResY": 1216}}}, {"Crop": "5:4", "Subs": {"Size L": {"ResX": 4640, "ResY": 3712}, "Size M": {"ResX": 3472, "ResY": 2784}, "Size S": {"ResX": 2320, "ResY": 1856}}}, {"Crop": "1.2x", "Subs": {"Size L": {"ResX": 4640, "ResY": 3088}, "Size M": {"ResX": 3472, "ResY": 2312}, "Size S": {"ResX": 2320, "ResY": 1544}}}, {"Crop": "1:1", "Subs": {"Size L": {"ResX": 3712, "ResY": 3712}, "Size M": {"ResX": 2784, "ResY": 2784}, "Size S": {"ResX": 1856, "ResY": 1856}}}, {"Crop": "16:9", "Subs": {"Size L": {"ResX": 5568, "ResY": 3128}, "Size M": {"ResX": 4176, "ResY": 2344}, "Size S": {"ResX": 2784, "ResY": 1560}}}]} | AR10: {=_xlfn.LET(_xlpm.crop,$R$2:$AO$2,_xlpm.size,$R$3:$AO$3,_xlpm.value,R10:AO10,_xlpm.vf,_xlfn.MAP(_xlpm.size,_xlpm.value,_xlfn.LAMBDA(_xlpm.s,_xlpm.v,IF(_xlpm.v="","",""""&_xlpm.s&""": {""ResX"": "&_xlfn.TEXTBEFORE(_xlpm.v,"x")&", ""ResY"": "&_xlfn.TEXTAFTER(_xlpm.v,"x")&"}"))),_xlpm.vfc,_xlfn.GROUPBY(TRANSPOSE(_xlpm.crop),TRANSPOSE(_xlpm.vf),_xlfn.LAMBDA(_xlpm.v,_xlfn.TEXTJOIN(", ",TRUE,_xlpm.v)),0,0),_xlpm.vfcc,_xlfn.BYROW(_xlpm.vfc,_xlfn.LAMBDA(_xlpm.r,IF(INDEX(_xlpm.r,1,2)="","","{""Crop"": """&INDEX(_xlpm.r,1,1)&""", ""Subs"": {"&INDEX(_xlpm.r,1,2)&"}}"))),_xlpm.vs,_xlfn.SORTBY(_xlpm.vfcc,MATCH(INDEX(_xlpm.vfc,0,1),_xlpm.crop,0)),"""CropSubSampling"": ["&_xlfn.TEXTJOIN(", ",TRUE,_xlpm.vs)&"]")} -> "CropSubSampling": [{"Crop": "FX", "Subs": {"Size L": {"ResX": 5568, "ResY": 3712}, "Size M": {"ResX": 4176, "ResY": 2784}, "Size S": {"ResX": 2784, "ResY": 1856}}}, {"Crop": "DX", "Subs": {"Size L": {"ResX": 3648, "ResY": 2432}, "Size M": {"ResX": 2736, "ResY": 1824}, "Size S": {"ResX": 1824, "ResY": 1216}}}, {"Crop": "5:4", "Subs": {"Size L": {"ResX": 4640, "ResY": 3712}, "Size M": {"ResX": 3472, "ResY": 2784}, "Size S": {"ResX": 2320, "ResY": 1856}}}, {"Crop": "1.2x", "Subs": {"Size L": {"ResX": 4640, "ResY": 3088}, "Size M": {"ResX": 3472, "ResY": 2312}, "Size S": {"ResX": 2320, "ResY": 1544}}}, {"Crop": "1:1", "Subs": {"Size L": {"ResX": 3712, "ResY": 3712}, "Size M": {"ResX": 2784, "ResY": 2784}, "Size S": {"ResX": 1856, "ResY": 1856}}}, {"Crop": "16:9", "Subs": {"Size L": {"ResX": 5568, "ResY": 3128}, "Size M": {"ResX": 4176, "ResY": 2344}, "Size S": {"ResX": 2784, "ResY": 1560}}}]
A11: D40 | B11: D40 | C11: 2006 | F11: Sony ICX-453-AQ | G11: CCD | I11: 12 | J11: 3008 | K11: 2000 | L11: 23.7 | M11: 15.6 | N11: 7.85 | O11: 7.85 | U11: 3008x2000 | V11: 2256x1496 | W11: 1504x1000 | AQ11: =""""&B11&""": {"&"""Name"": "&""""&A11&""", "&"""Year"": "&C11&", "&"""Processor"": "&""""&D11&""", "&"""Sensor"": {"&"""Name"": "&""""&F11&""", "&"""Type"": "&""""&G11&""", "&"""Bayer"": "&""""&H11&""", "&"""BitDepth"": "&""&I11&", "&"""ResX"": "&""&J11&", "&"""ResY"": "&""&K11&", "&"""SizeX"": "&""&SUBSTITUTE(L11,",",".")&", "&"""SizeY"": "&""&SUBSTITUTE(M11,",",".")&", "&"""PixelSizeX"": "&""&SUBSTITUTE(N11,",",".")&", "&"""PixelSizeY"": "&""&SUBSTITUTE(O11,",",".")&"}, "&AR11&"}" -> "D40": {"Name": "D40", "Year": 2006, "Processor": "", "Sensor": {"Name": "Sony ICX-453-AQ", "Type": "CCD", "Bayer": "", "BitDepth": 12, "ResX": 3008, "ResY": 2000, "SizeX": 23.7, "SizeY": 15.6, "PixelSizeX": 7.85, "PixelSizeY": 7.85}, "CropSubSampling": [{"Crop": "DX", "Subs": {"Size L": {"ResX": 3008, "ResY": 2000}, "Size M": {"ResX": 2256, "ResY": 1496}, "Size S": {"ResX": 1504, "ResY": 1000}}}]} | AR11: {=_xlfn.LET(_xlpm.crop,$R$2:$AO$2,_xlpm.size,$R$3:$AO$3,_xlpm.value,R11:AO11,_xlpm.vf,_xlfn.MAP(_xlpm.size,_xlpm.value,_xlfn.LAMBDA(_xlpm.s,_xlpm.v,IF(_xlpm.v="","",""""&_xlpm.s&""": {""ResX"": "&_xlfn.TEXTBEFORE(_xlpm.v,"x")&", ""ResY"": "&_xlfn.TEXTAFTER(_xlpm.v,"x")&"}"))),_xlpm.vfc,_xlfn.GROUPBY(TRANSPOSE(_xlpm.crop),TRANSPOSE(_xlpm.vf),_xlfn.LAMBDA(_xlpm.v,_xlfn.TEXTJOIN(", ",TRUE,_xlpm.v)),0,0),_xlpm.vfcc,_xlfn.BYROW(_xlpm.vfc,_xlfn.LAMBDA(_xlpm.r,IF(INDEX(_xlpm.r,1,2)="","","{""Crop"": """&INDEX(_xlpm.r,1,1)&""", ""Subs"": {"&INDEX(_xlpm.r,1,2)&"}}"))),_xlpm.vs,_xlfn.SORTBY(_xlpm.vfcc,MATCH(INDEX(_xlpm.vfc,0,1),_xlpm.crop,0)),"""CropSubSampling"": ["&_xlfn.TEXTJOIN(", ",TRUE,_xlpm.vs)&"]")} -> "CropSubSampling": [{"Crop": "DX", "Subs": {"Size L": {"ResX": 3008, "ResY": 2000}, "Size M": {"ResX": 2256, "ResY": 1496}, "Size S": {"ResX": 1504, "ResY": 1000}}}]
A12: D40X | B12: D40X | C12: 2007 | F12: Sony ICX-493-AQA | G12: CCD | I12: 12 | J12: 3872 | K12: 2592 | L12: 23.6 | M12: 15.8 | N12: 6.11 | O12: 6.11 | U12: 3872x2592 | V12: 2896x1944 | W12: 1936x1296 | AQ12: =""""&B12&""": {"&"""Name"": "&""""&A12&""", "&"""Year"": "&C12&", "&"""Processor"": "&""""&D12&""", "&"""Sensor"": {"&"""Name"": "&""""&F12&""", "&"""Type"": "&""""&G12&""", "&"""Bayer"": "&""""&H12&""", "&"""BitDepth"": "&""&I12&", "&"""ResX"": "&""&J12&", "&"""ResY"": "&""&K12&", "&"""SizeX"": "&""&SUBSTITUTE(L12,",",".")&", "&"""SizeY"": "&""&SUBSTITUTE(M12,",",".")&", "&"""PixelSizeX"": "&""&SUBSTITUTE(N12,",",".")&", "&"""PixelSizeY"": "&""&SUBSTITUTE(O12,",",".")&"}, "&AR12&"}" -> "D40X": {"Name": "D40X", "Year": 2007, "Processor": "", "Sensor": {"Name": "Sony ICX-493-AQA", "Type": "CCD", "Bayer": "", "BitDepth": 12, "ResX": 3872, "ResY": 2592, "SizeX": 23.6, "SizeY": 15.8, "PixelSizeX": 6.11, "PixelSizeY": 6.11}, "CropSubSampling": [{"Crop": "DX", "Subs": {"Size L": {"ResX": 3872, "ResY": 2592}, "Size M": {"ResX": 2896, "ResY": 1944}, "Size S": {"ResX": 1936, "ResY": 1296}}}]} | AR12: {=_xlfn.LET(_xlpm.crop,$R$2:$AO$2,_xlpm.size,$R$3:$AO$3,_xlpm.value,R12:AO12,_xlpm.vf,_xlfn.MAP(_xlpm.size,_xlpm.value,_xlfn.LAMBDA(_xlpm.s,_xlpm.v,IF(_xlpm.v="","",""""&_xlpm.s&""": {""ResX"": "&_xlfn.TEXTBEFORE(_xlpm.v,"x")&", ""ResY"": "&_xlfn.TEXTAFTER(_xlpm.v,"x")&"}"))),_xlpm.vfc,_xlfn.GROUPBY(TRANSPOSE(_xlpm.crop),TRANSPOSE(_xlpm.vf),_xlfn.LAMBDA(_xlpm.v,_xlfn.TEXTJOIN(", ",TRUE,_xlpm.v)),0,0),_xlpm.vfcc,_xlfn.BYROW(_xlpm.vfc,_xlfn.LAMBDA(_xlpm.r,IF(INDEX(_xlpm.r,1,2)="","","{""Crop"": """&INDEX(_xlpm.r,1,1)&""", ""Subs"": {"&INDEX(_xlpm.r,1,2)&"}}"))),_xlpm.vs,_xlfn.SORTBY(_xlpm.vfcc,MATCH(INDEX(_xlpm.vfc,0,1),_xlpm.crop,0)),"""CropSubSampling"": ["&_xlfn.TEXTJOIN(", ",TRUE,_xlpm.vs)&"]")} -> "CropSubSampling": [{"Crop": "DX", "Subs": {"Size L": {"ResX": 3872, "ResY": 2592}, "Size M": {"ResX": 2896, "ResY": 1944}, "Size S": {"ResX": 1936, "ResY": 1296}}}]
A13: D60 | B13: D60 | C13: 2008 | D13: EXPEED | F13: Sony ICX-493-AQA | G13: CCD | I13: 12 | J13: 3872 | K13: 2592 | L13: 23.6 | M13: 15.8 | N13: 6.11 | O13: 6.11 | U13: 3872x2592 | V13: 2896x1944 | W13: 1936x1296 | AQ13: =""""&B13&""": {"&"""Name"": "&""""&A13&""", "&"""Year"": "&C13&", "&"""Processor"": "&""""&D13&""", "&"""Sensor"": {"&"""Name"": "&""""&F13&""", "&"""Type"": "&""""&G13&""", "&"""Bayer"": "&""""&H13&""", "&"""BitDepth"": "&""&I13&", "&"""ResX"": "&""&J13&", "&"""ResY"": "&""&K13&", "&"""SizeX"": "&""&SUBSTITUTE(L13,",",".")&", "&"""SizeY"": "&""&SUBSTITUTE(M13,",",".")&", "&"""PixelSizeX"": "&""&SUBSTITUTE(N13,",",".")&", "&"""PixelSizeY"": "&""&SUBSTITUTE(O13,",",".")&"}, "&AR13&"}" -> "D60": {"Name": "D60", "Year": 2008, "Processor": "EXPEED", "Sensor": {"Name": "Sony ICX-493-AQA", "Type": "CCD", "Bayer": "", "BitDepth": 12, "ResX": 3872, "ResY": 2592, "SizeX": 23.6, "SizeY": 15.8, "PixelSizeX": 6.11, "PixelSizeY": 6.11}, "CropSubSampling": [{"Crop": "DX", "Subs": {"Size L": {"ResX": 3872, "ResY": 2592}, "Size M": {"ResX": 2896, "ResY": 1944}, "Size S": {"ResX": 1936, "ResY": 1296}}}]} | AR13: {=_xlfn.LET(_xlpm.crop,$R$2:$AO$2,_xlpm.size,$R$3:$AO$3,_xlpm.value,R13:AO13,_xlpm.vf,_xlfn.MAP(_xlpm.size,_xlpm.value,_xlfn.LAMBDA(_xlpm.s,_xlpm.v,IF(_xlpm.v="","",""""&_xlpm.s&""": {""ResX"": "&_xlfn.TEXTBEFORE(_xlpm.v,"x")&", ""ResY"": "&_xlfn.TEXTAFTER(_xlpm.v,"x")&"}"))),_xlpm.vfc,_xlfn.GROUPBY(TRANSPOSE(_xlpm.crop),TRANSPOSE(_xlpm.vf),_xlfn.LAMBDA(_xlpm.v,_xlfn.TEXTJOIN(", ",TRUE,_xlpm.v)),0,0),_xlpm.vfcc,_xlfn.BYROW(_xlpm.vfc,_xlfn.LAMBDA(_xlpm.r,IF(INDEX(_xlpm.r,1,2)="","","{""Crop"": """&INDEX(_xlpm.r,1,1)&""", ""Subs"": {"&INDEX(_xlpm.r,1,2)&"}}"))),_xlpm.vs,_xlfn.SORTBY(_xlpm.vfcc,MATCH(INDEX(_xlpm.vfc,0,1),_xlpm.crop,0)),"""CropSubSampling"": ["&_xlfn.TEXTJOIN(", ",TRUE,_xlpm.vs)&"]")} -> "CropSubSampling": [{"Crop": "DX", "Subs": {"Size L": {"ResX": 3872, "ResY": 2592}, "Size M": {"ResX": 2896, "ResY": 1944}, "Size S": {"ResX": 1936, "ResY": 1296}}}]
A14: D80 | B14: D80 | C14: 2006 | F14: Sony ICX-493-AQA | G14: CCD | H14: GBRG | I14: 12 | J14: 3872 | K14: 2592 | L14: 23.6 | M14: 15.8 | N14: 6.11 | O14: 6.11 | U14: 3872x2592 | V14: 2896x1944 | W14: 1936x1296 | AQ14: =""""&B14&""": {"&"""Name"": "&""""&A14&""", "&"""Year"": "&C14&", "&"""Processor"": "&""""&D14&""", "&"""Sensor"": {"&"""Name"": "&""""&F14&""", "&"""Type"": "&""""&G14&""", "&"""Bayer"": "&""""&H14&""", "&"""BitDepth"": "&""&I14&", "&"""ResX"": "&""&J14&", "&"""ResY"": "&""&K14&", "&"""SizeX"": "&""&SUBSTITUTE(L14,",",".")&", "&"""SizeY"": "&""&SUBSTITUTE(M14,",",".")&", "&"""PixelSizeX"": "&""&SUBSTITUTE(N14,",",".")&", "&"""PixelSizeY"": "&""&SUBSTITUTE(O14,",",".")&"}, "&AR14&"}" -> "D80": {"Name": "D80", "Year": 2006, "Processor": "", "Sensor": {"Name": "Sony ICX-493-AQA", "Type": "CCD", "Bayer": "GBRG", "BitDepth": 12, "ResX": 3872, "ResY": 2592, "SizeX": 23.6, "SizeY": 15.8, "PixelSizeX": 6.11, "PixelSizeY": 6.11}, "CropSubSampling": [{"Crop": "DX", "Subs": {"Size L": {"ResX": 3872, "ResY": 2592}, "Size M": {"ResX": 2896, "ResY": 1944}, "Size S": {"ResX": 1936, "ResY": 1296}}}]} | AR14: {=_xlfn.LET(_xlpm.crop,$R$2:$AO$2,_xlpm.size,$R$3:$AO$3,_xlpm.value,R14:AO14,_xlpm.vf,_xlfn.MAP(_xlpm.size,_xlpm.value,_xlfn.LAMBDA(_xlpm.s,_xlpm.v,IF(_xlpm.v="","",""""&_xlpm.s&""": {""ResX"": "&_xlfn.TEXTBEFORE(_xlpm.v,"x")&", ""ResY"": "&_xlfn.TEXTAFTER(_xlpm.v,"x")&"}"))),_xlpm.vfc,_xlfn.GROUPBY(TRANSPOSE(_xlpm.crop),TRANSPOSE(_xlpm.vf),_xlfn.LAMBDA(_xlpm.v,_xlfn.TEXTJOIN(", ",TRUE,_xlpm.v)),0,0),_xlpm.vfcc,_xlfn.BYROW(_xlpm.vfc,_xlfn.LAMBDA(_xlpm.r,IF(INDEX(_xlpm.r,1,2)="","","{""Crop"": """&INDEX(_xlpm.r,1,1)&""", ""Subs"": {"&INDEX(_xlpm.r,1,2)&"}}"))),_xlpm.vs,_xlfn.SORTBY(_xlpm.vfcc,MATCH(INDEX(_xlpm.vfc,0,1),_xlpm.crop,0)),"""CropSubSampling"": ["&_xlfn.TEXTJOIN(", ",TRUE,_xlpm.vs)&"]")} -> "CropSubSampling": [{"Crop": "DX", "Subs": {"Size L": {"ResX": 3872, "ResY": 2592}, "Size M": {"ResX": 2896, "ResY": 1944}, "Size S": {"ResX": 1936, "ResY": 1296}}}]
A15: D90 | B15: D90 | C15: 2008 | D15: EXPEED | F15: Sony IMX-038-BQL | G15: CMOS | I15: 12 | J15: 4288 | K15: 2848 | L15: 23.6 | M15: 15.8 | N15: 5.53 | O15: 5.53 | U15: 4288x2848 | V15: 3216x2136 | W15: 2144x1424 | AQ15: =""""&B15&""": {"&"""Name"": "&""""&A15&""", "&"""Year"": "&C15&", "&"""Processor"": "&""""&D15&""", "&"""Sensor"": {"&"""Name"": "&""""&F15&""", "&"""Type"": "&""""&G15&""", "&"""Bayer"": "&""""&H15&""", "&"""BitDepth"": "&""&I15&", "&"""ResX"": "&""&J15&", "&"""ResY"": "&""&K15&", "&"""SizeX"": "&""&SUBSTITUTE(L15,",",".")&", "&"""SizeY"": "&""&SUBSTITUTE(M15,",",".")&", "&"""PixelSizeX"": "&""&SUBSTITUTE(N15,",",".")&", "&"""PixelSizeY"": "&""&SUBSTITUTE(O15,",",".")&"}, "&AR15&"}" -> "D90": {"Name": "D90", "Year": 2008, "Processor": "EXPEED", "Sensor": {"Name": "Sony IMX-038-BQL", "Type": "CMOS", "Bayer": "", "BitDepth": 12, "ResX": 4288, "ResY": 2848, "SizeX": 23.6, "SizeY": 15.8, "PixelSizeX": 5.53, "PixelSizeY": 5.53}, "CropSubSampling": [{"Crop": "DX", "Subs": {"Size L": {"ResX": 4288, "ResY": 2848}, "Size M": {"ResX": 3216, "ResY": 2136}, "Size S": {"ResX": 2144, "ResY": 1424}}}]} | AR15: {=_xlfn.LET(_xlpm.crop,$R$2:$AO$2,_xlpm.size,$R$3:$AO$3,_xlpm.value,R15:AO15,_xlpm.vf,_xlfn.MAP(_xlpm.size,_xlpm.value,_xlfn.LAMBDA(_xlpm.s,_xlpm.v,IF(_xlpm.v="","",""""&_xlpm.s&""": {""ResX"": "&_xlfn.TEXTBEFORE(_xlpm.v,"x")&", ""ResY"": "&_xlfn.TEXTAFTER(_xlpm.v,"x")&"}"))),_xlpm.vfc,_xlfn.GROUPBY(TRANSPOSE(_xlpm.crop),TRANSPOSE(_xlpm.vf),_xlfn.LAMBDA(_xlpm.v,_xlfn.TEXTJOIN(", ",TRUE,_xlpm.v)),0,0),_xlpm.vfcc,_xlfn.BYROW(_xlpm.vfc,_xlfn.LAMBDA(_xlpm.r,IF(INDEX(_xlpm.r,1,2)="","","{""Crop"": """&INDEX(_xlpm.r,1,1)&""", ""Subs"": {"&INDEX(_xlpm.r,1,2)&"}}"))),_xlpm.vs,_xlfn.SORTBY(_xlpm.vfcc,MATCH(INDEX(_xlpm.vfc,0,1),_xlpm.crop,0)),"""CropSubSampling"": ["&_xlfn.TEXTJOIN(", ",TRUE,_xlpm.vs)&"]")} -> "CropSubSampling": [{"Crop": "DX", "Subs": {"Size L": {"ResX": 4288, "ResY": 2848}, "Size M": {"ResX": 3216, "ResY": 2136}, "Size S": {"ResX": 2144, "ResY": 1424}}}]
A16: D200 | B16: D200 | C16: 2005 | F16: Sony ICX-483-AQA | G16: CCD | I16: 12 | J16: 3872 | K16: 2592 | L16: 23.6 | M16: 15.8 | N16: 6.11 | O16: 6.11 | U16: 3872x2592 | V16: 2896x1944 | W16: 1936x1296 | AQ16: =""""&B16&""": {"&"""Name"": "&""""&A16&""", "&"""Year"": "&C16&", "&"""Processor"": "&""""&D16&""", "&"""Sensor"": {"&"""Name"": "&""""&F16&""", "&"""Type"": "&""""&G16&""", "&"""Bayer"": "&""""&H16&""", "&"""BitDepth"": "&""&I16&", "&"""ResX"": "&""&J16&", "&"""ResY"": "&""&K16&", "&"""SizeX"": "&""&SUBSTITUTE(L16,",",".")&", "&"""SizeY"": "&""&SUBSTITUTE(M16,",",".")&", "&"""PixelSizeX"": "&""&SUBSTITUTE(N16,",",".")&", "&"""PixelSizeY"": "&""&SUBSTITUTE(O16,",",".")&"}, "&AR16&"}" -> "D200": {"Name": "D200", "Year": 2005, "Processor": "", "Sensor": {"Name": "Sony ICX-483-AQA", "Type": "CCD", "Bayer": "", "BitDepth": 12, "ResX": 3872, "ResY": 2592, "SizeX": 23.6, "SizeY": 15.8, "PixelSizeX": 6.11, "PixelSizeY": 6.11}, "CropSubSampling": [{"Crop": "DX", "Subs": {"Size L": {"ResX": 3872, "ResY": 2592}, "Size M": {"ResX": 2896, "ResY": 1944}, "Size S": {"ResX": 1936, "ResY": 1296}}}]} | AR16: {=_xlfn.LET(_xlpm.crop,$R$2:$AO$2,_xlpm.size,$R$3:$AO$3,_xlpm.value,R16:AO16,_xlpm.vf,_xlfn.MAP(_xlpm.size,_xlpm.value,_xlfn.LAMBDA(_xlpm.s,_xlpm.v,IF(_xlpm.v="","",""""&_xlpm.s&""": {""ResX"": "&_xlfn.TEXTBEFORE(_xlpm.v,"x")&", ""ResY"": "&_xlfn.TEXTAFTER(_xlpm.v,"x")&"}"))),_xlpm.vfc,_xlfn.GROUPBY(TRANSPOSE(_xlpm.crop),TRANSPOSE(_xlpm.vf),_xlfn.LAMBDA(_xlpm.v,_xlfn.TEXTJOIN(", ",TRUE,_xlpm.v)),0,0),_xlpm.vfcc,_xlfn.BYROW(_xlpm.vfc,_xlfn.LAMBDA(_xlpm.r,IF(INDEX(_xlpm.r,1,2)="","","{""Crop"": """&INDEX(_xlpm.r,1,1)&""", ""Subs"": {"&INDEX(_xlpm.r,1,2)&"}}"))),_xlpm.vs,_xlfn.SORTBY(_xlpm.vfcc,MATCH(INDEX(_xlpm.vfc,0,1),_xlpm.crop,0)),"""CropSubSampling"": ["&_xlfn.TEXTJOIN(", ",TRUE,_xlpm.vs)&"]")} -> "CropSubSampling": [{"Crop": "DX", "Subs": {"Size L": {"ResX": 3872, "ResY": 2592}, "Size M": {"ResX": 2896, "ResY": 1944}, "Size S": {"ResX": 1936, "ResY": 1296}}}]
A17: D300 | B17: D300 | C17: 2007 | D17: EXPEED | F17: Sony IMX-021-BQR | G17: CMOS | I17: 14 | J17: 4288 | K17: 2848 | L17: 23.6 | M17: 15.8 | N17: 5.5 | O17: 5.5 | U17: 4288x2848 | V17: 3216x2136 | W17: 2144x1424 | AQ17: =""""&B17&""": {"&"""Name"": "&""""&A17&""", "&"""Year"": "&C17&", "&"""Processor"": "&""""&D17&""", "&"""Sensor"": {"&"""Name"": "&""""&F17&""", "&"""Type"": "&""""&G17&""", "&"""Bayer"": "&""""&H17&""", "&"""BitDepth"": "&""&I17&", "&"""ResX"": "&""&J17&", "&"""ResY"": "&""&K17&", "&"""SizeX"": "&""&SUBSTITUTE(L17,",",".")&", "&"""SizeY"": "&""&SUBSTITUTE(M17,",",".")&", "&"""PixelSizeX"": "&""&SUBSTITUTE(N17,",",".")&", "&"""PixelSizeY"": "&""&SUBSTITUTE(O17,",",".")&"}, "&AR17&"}" -> "D300": {"Name": "D300", "Year": 2007, "Processor": "EXPEED", "Sensor": {"Name": "Sony IMX-021-BQR", "Type": "CMOS", "Bayer": "", "BitDepth": 14, "ResX": 4288, "ResY": 2848, "SizeX": 23.6, "SizeY": 15.8, "PixelSizeX": 5.5, "PixelSizeY": 5.5}, "CropSubSampling": [{"Crop": "DX", "Subs": {"Size L": {"ResX": 4288, "ResY": 2848}, "Size M": {"ResX": 3216, "ResY": 2136}, "Size S": {"ResX": 2144, "ResY": 1424}}}]} | AR17: {=_xlfn.LET(_xlpm.crop,$R$2:$AO$2,_xlpm.size,$R$3:$AO$3,_xlpm.value,R17:AO17,_xlpm.vf,_xlfn.MAP(_xlpm.size,_xlpm.value,_xlfn.LAMBDA(_xlpm.s,_xlpm.v,IF(_xlpm.v="","",""""&_xlpm.s&""": {""ResX"": "&_xlfn.TEXTBEFORE(_xlpm.v,"x")&", ""ResY"": "&_xlfn.TEXTAFTER(_xlpm.v,"x")&"}"))),_xlpm.vfc,_xlfn.GROUPBY(TRANSPOSE(_xlpm.crop),TRANSPOSE(_xlpm.vf),_xlfn.LAMBDA(_xlpm.v,_xlfn.TEXTJOIN(", ",TRUE,_xlpm.v)),0,0),_xlpm.vfcc,_xlfn.BYROW(_xlpm.vfc,_xlfn.LAMBDA(_xlpm.r,IF(INDEX(_xlpm.r,1,2)="","","{""Crop"": """&INDEX(_xlpm.r,1,1)&""", ""Subs"": {"&INDEX(_xlpm.r,1,2)&"}}"))),_xlpm.vs,_xlfn.SORTBY(_xlpm.vfcc,MATCH(INDEX(_xlpm.vfc,0,1),_xlpm.crop,0)),"""CropSubSampling"": ["&_xlfn.TEXTJOIN(", ",TRUE,_xlpm.vs)&"]")} -> "CropSubSampling": [{"Crop": "DX", "Subs": {"Size L": {"ResX": 4288, "ResY": 2848}, "Size M": {"ResX": 3216, "ResY": 2136}, "Size S": {"ResX": 2144, "ResY": 1424}}}]
A18: D300S | B18: D300S | C18: 2009 | D18: EXPEED | F18: Sony IMX-038-BQL | G18: CMOS | I18: 14 | J18: 4288 | K18: 2848 | L18: 23.6 | M18: 15.8 | N18: 5.5 | O18: 5.5 | U18: 4288x2848 | V18: 3216x2136 | W18: 2144x1424 | AQ18: =""""&B18&""": {"&"""Name"": "&""""&A18&""", "&"""Year"": "&C18&", "&"""Processor"": "&""""&D18&""", "&"""Sensor"": {"&"""Name"": "&""""&F18&""", "&"""Type"": "&""""&G18&""", "&"""Bayer"": "&""""&H18&""", "&"""BitDepth"": "&""&I18&", "&"""ResX"": "&""&J18&", "&"""ResY"": "&""&K18&", "&"""SizeX"": "&""&SUBSTITUTE(L18,",",".")&", "&"""SizeY"": "&""&SUBSTITUTE(M18,",",".")&", "&"""PixelSizeX"": "&""&SUBSTITUTE(N18,",",".")&", "&"""PixelSizeY"": "&""&SUBSTITUTE(O18,",",".")&"}, "&AR18&"}" -> "D300S": {"Name": "D300S", "Year": 2009, "Processor": "EXPEED", "Sensor": {"Name": "Sony IMX-038-BQL", "Type": "CMOS", "Bayer": "", "BitDepth": 14, "ResX": 4288, "ResY": 2848, "SizeX": 23.6, "SizeY": 15.8, "PixelSizeX": 5.5, "PixelSizeY": 5.5}, "CropSubSampling": [{"Crop": "DX", "Subs": {"Size L": {"ResX": 4288, "ResY": 2848}, "Size M": {"ResX": 3216, "ResY": 2136}, "Size S": {"ResX": 2144, "ResY": 1424}}}]} | AR18: {=_xlfn.LET(_xlpm.crop,$R$2:$AO$2,_xlpm.size,$R$3:$AO$3,_xlpm.value,R18:AO18,_xlpm.vf,_xlfn.MAP(_xlpm.size,_xlpm.value,_xlfn.LAMBDA(_xlpm.s,_xlpm.v,IF(_xlpm.v="","",""""&_xlpm.s&""": {""ResX"": "&_xlfn.TEXTBEFORE(_xlpm.v,"x")&", ""ResY"": "&_xlfn.TEXTAFTER(_xlpm.v,"x")&"}"))),_xlpm.vfc,_xlfn.GROUPBY(TRANSPOSE(_xlpm.crop),TRANSPOSE(_xlpm.vf),_xlfn.LAMBDA(_xlpm.v,_xlfn.TEXTJOIN(", ",TRUE,_xlpm.v)),0,0),_xlpm.vfcc,_xlfn.BYROW(_xlpm.vfc,_xlfn.LAMBDA(_xlpm.r,IF(INDEX(_xlpm.r,1,2)="","","{""Crop"": """&INDEX(_xlpm.r,1,1)&""", ""Subs"": {"&INDEX(_xlpm.r,1,2)&"}}"))),_xlpm.vs,_xlfn.SORTBY(_xlpm.vfcc,MATCH(INDEX(_xlpm.vfc,0,1),_xlpm.crop,0)),"""CropSubSampling"": ["&_xlfn.TEXTJOIN(", ",TRUE,_xlpm.vs)&"]")} -> "CropSubSampling": [{"Crop": "DX", "Subs": {"Size L": {"ResX": 4288, "ResY": 2848}, "Size M": {"ResX": 3216, "ResY": 2136}, "Size S": {"ResX": 2144, "ResY": 1424}}}]
A19: D500 | B19: D500 | C19: 2016 | D19: EXPEED 5 | F19: Sony IMX-321 | G19: CMOS | I19: 14 | J19: 5568 | K19: 3712 | L19: 23.5 | M19: 15.7 | N19: 4.22 | O19: 4.22 | Q19: DX 0, 1.3x 1 | U19: 5568x3712 | V19: 4176x2784 | W19: 2784x1856 | AA19: 4272x2848 | AB19: 3200x2136 | AC19: 2128x1424 | AQ19: =""""&B19&""": {"&"""Name"": "&""""&A19&""", "&"""Year"": "&C19&", "&"""Processor"": "&""""&D19&""", "&"""Sensor"": {"&"""Name"": "&""""&F19&""", "&"""Type"": "&""""&G19&""", "&"""Bayer"": "&""""&H19&""", "&"""BitDepth"": "&""&I19&", "&"""ResX"": "&""&J19&", "&"""ResY"": "&""&K19&", "&"""SizeX"": "&""&SUBSTITUTE(L19,",",".")&", "&"""SizeY"": "&""&SUBSTITUTE(M19,",",".")&", "&"""PixelSizeX"": "&""&SUBSTITUTE(N19,",",".")&", "&"""PixelSizeY"": "&""&SUBSTITUTE(O19,",",".")&"}, "&AR19&"}" -> "D500": {"Name": "D500", "Year": 2016, "Processor": "EXPEED 5", "Sensor": {"Name": "Sony IMX-321", "Type": "CMOS", "Bayer": "", "BitDepth": 14, "ResX": 5568, "ResY": 3712, "SizeX": 23.5, "SizeY": 15.7, "PixelSizeX": 4.22, "PixelSizeY": 4.22}, "CropSubSampling": [{"Crop": "DX", "Subs": {"Size L": {"ResX": 5568, "ResY": 3712}, "Size M": {"ResX": 4176, "ResY": 2784}, "Size S": {"ResX": 2784, "ResY": 1856}}}, {"Crop": "1.3x", "Subs": {"Size L": {"ResX": 4272, "ResY": 2848}, "Size M": {"ResX": 3200, "ResY": 2136}, "Size S": {"ResX": 2128, "ResY": 1424}}}]} | AR19: {=_xlfn.LET(_xlpm.crop,$R$2:$AO$2,_xlpm.size,$R$3:$AO$3,_xlpm.value,R19:AO19,_xlpm.vf,_xlfn.MAP(_xlpm.size,_xlpm.value,_xlfn.LAMBDA(_xlpm.s,_xlpm.v,IF(_xlpm.v="","",""""&_xlpm.s&""": {""ResX"": "&_xlfn.TEXTBEFORE(_xlpm.v,"x")&", ""ResY"": "&_xlfn.TEXTAFTER(_xlpm.v,"x")&"}"))),_xlpm.vfc,_xlfn.GROUPBY(TRANSPOSE(_xlpm.crop),TRANSPOSE(_xlpm.vf),_xlfn.LAMBDA(_xlpm.v,_xlfn.TEXTJOIN(", ",TRUE,_xlpm.v)),0,0),_xlpm.vfcc,_xlfn.BYROW(_xlpm.vfc,_xlfn.LAMBDA(_xlpm.r,IF(INDEX(_xlpm.r,1,2)="","","{""Crop"": """&INDEX(_xlpm.r,1,1)&""", ""Subs"": {"&INDEX(_xlpm.r,1,2)&"}}"))),_xlpm.vs,_xlfn.SORTBY(_xlpm.vfcc,MATCH(INDEX(_xlpm.vfc,0,1),_xlpm.crop,0)),"""CropSubSampling"": ["&_xlfn.TEXTJOIN(", ",TRUE,_xlpm.vs)&"]")} -> "CropSubSampling": [{"Crop": "DX", "Subs": {"Size L": {"ResX": 5568, "ResY": 3712}, "Size M": {"ResX": 4176, "ResY": 2784}, "Size S": {"ResX": 2784, "ResY": 1856}}}, {"Crop": "1.3x", "Subs": {"Size L": {"ResX": 4272, "ResY": 2848}, "Size M": {"ResX": 3200, "ResY": 2136}, "Size S": {"ResX": 2128, "ResY": 1424}}}]
A20: D600 | B20: D600 | C20: 2012 | D20: EXPEED 3 | F20: Sony IMX-128- (L) -AQP | G20: CMOS | I20: 14 | J20: 6016 | K20: 4016 | L20: 35.9 | M20: 24 | N20: 5.95 | O20: 5.95 | Q20: FX 0, DX 1 | R20: 6016x4016 | S20: 4512x3008 | T20: 3008x2008 | U20: 3936x2624 | V20: 2944x1968 | W20: 1968x1312 | AQ20: =""""&B20&""": {"&"""Name"": "&""""&A20&""", "&"""Year"": "&C20&", "&"""Processor"": "&""""&D20&""", "&"""Sensor"": {"&"""Name"": "&""""&F20&""", "&"""Type"": "&""""&G20&""", "&"""Bayer"": "&""""&H20&""", "&"""BitDepth"": "&""&I20&", "&"""ResX"": "&""&J20&", "&"""ResY"": "&""&K20&", "&"""SizeX"": "&""&SUBSTITUTE(L20,",",".")&", "&"""SizeY"": "&""&SUBSTITUTE(M20,",",".")&", "&"""PixelSizeX"": "&""&SUBSTITUTE(N20,",",".")&", "&"""PixelSizeY"": "&""&SUBSTITUTE(O20,",",".")&"}, "&AR20&"}" -> "D600": {"Name": "D600", "Year": 2012, "Processor": "EXPEED 3", "Sensor": {"Name": "Sony IMX-128- (L) -AQP", "Type": "CMOS", "Bayer": "", "BitDepth": 14, "ResX": 6016, "ResY": 4016, "SizeX": 35.9, "SizeY": 24, "PixelSizeX": 5.95, "PixelSizeY": 5.95}, "CropSubSampling": [{"Crop": "FX", "Subs": {"Size L": {"ResX": 6016, "ResY": 4016}, "Size M": {"ResX": 4512, "ResY": 3008}, "Size S": {"ResX": 3008, "ResY": 2008}}}, {"Crop": "DX", "Subs": {"Size L": {"ResX": 3936, "ResY": 2624}, "Size M": {"ResX": 2944, "ResY": 1968}, "Size S": {"ResX": 1968, "ResY": 1312}}}]} | AR20: {=_xlfn.LET(_xlpm.crop,$R$2:$AO$2,_xlpm.size,$R$3:$AO$3,_xlpm.value,R20:AO20,_xlpm.vf,_xlfn.MAP(_xlpm.size,_xlpm.value,_xlfn.LAMBDA(_xlpm.s,_xlpm.v,IF(_xlpm.v="","",""""&_xlpm.s&""": {""ResX"": "&_xlfn.TEXTBEFORE(_xlpm.v,"x")&", ""ResY"": "&_xlfn.TEXTAFTER(_xlpm.v,"x")&"}"))),_xlpm.vfc,_xlfn.GROUPBY(TRANSPOSE(_xlpm.crop),TRANSPOSE(_xlpm.vf),_xlfn.LAMBDA(_xlpm.v,_xlfn.TEXTJOIN(", ",TRUE,_xlpm.v)),0,0),_xlpm.vfcc,_xlfn.BYROW(_xlpm.vfc,_xlfn.LAMBDA(_xlpm.r,IF(INDEX(_xlpm.r,1,2)="","","{""Crop"": """&INDEX(_xlpm.r,1,1)&""", ""Subs"": {"&INDEX(_xlpm.r,1,2)&"}}"))),_xlpm.vs,_xlfn.SORTBY(_xlpm.vfcc,MATCH(INDEX(_xlpm.vfc,0,1),_xlpm.crop,0)),"""CropSubSampling"": ["&_xlfn.TEXTJOIN(", ",TRUE,_xlpm.vs)&"]")} -> "CropSubSampling": [{"Crop": "FX", "Subs": {"Size L": {"ResX": 6016, "ResY": 4016}, "Size M": {"ResX": 4512, "ResY": 3008}, "Size S": {"ResX": 3008, "ResY": 2008}}}, {"Crop": "DX", "Subs": {"Size L": {"ResX": 3936, "ResY": 2624}, "Size M": {"ResX": 2944, "ResY": 1968}, "Size S": {"ResX": 1968, "ResY": 1312}}}]
A21: D610 | B21: D610 | C21: 2013 | D21: EXPEED 3 | F21: Sony IMX-128- (L) -AQP | G21: CMOS | I21: 14 | J21: 6016 | K21: 4016 | L21: 35.9 | M21: 24 | N21: 5.95 | O21: 5.95 | Q21: FX 0, DX 1 | R21: 6016x4016 | S21: 4512x3008 | T21: 3008x2008 | U21: 3936x2624 | V21: 2944x1968 | W21: 1968x1312 | AQ21: =""""&B21&""": {"&"""Name"": "&""""&A21&""", "&"""Year"": "&C21&", "&"""Processor"": "&""""&D21&""", "&"""Sensor"": {"&"""Name"": "&""""&F21&""", "&"""Type"": "&""""&G21&""", "&"""Bayer"": "&""""&H21&""", "&"""BitDepth"": "&""&I21&", "&"""ResX"": "&""&J21&", "&"""ResY"": "&""&K21&", "&"""SizeX"": "&""&SUBSTITUTE(L21,",",".")&", "&"""SizeY"": "&""&SUBSTITUTE(M21,",",".")&", "&"""PixelSizeX"": "&""&SUBSTITUTE(N21,",",".")&", "&"""PixelSizeY"": "&""&SUBSTITUTE(O21,",",".")&"}, "&AR21&"}" -> "D610": {"Name": "D610", "Year": 2013, "Processor": "EXPEED 3", "Sensor": {"Name": "Sony IMX-128- (L) -AQP", "Type": "CMOS", "Bayer": "", "BitDepth": 14, "ResX": 6016, "ResY": 4016, "SizeX": 35.9, "SizeY": 24, "PixelSizeX": 5.95, "PixelSizeY": 5.95}, "CropSubSampling": [{"Crop": "FX", "Subs": {"Size L": {"ResX": 6016, "ResY": 4016}, "Size M": {"ResX": 4512, "ResY": 3008}, "Size S": {"ResX": 3008, "ResY": 2008}}}, {"Crop": "DX", "Subs": {"Size L": {"ResX": 3936, "ResY": 2624}, "Size M": {"ResX": 2944, "ResY": 1968}, "Size S": {"ResX": 1968, "ResY": 1312}}}]} | AR21: {=_xlfn.LET(_xlpm.crop,$R$2:$AO$2,_xlpm.size,$R$3:$AO$3,_xlpm.value,R21:AO21,_xlpm.vf,_xlfn.MAP(_xlpm.size,_xlpm.value,_xlfn.LAMBDA(_xlpm.s,_xlpm.v,IF(_xlpm.v="","",""""&_xlpm.s&""": {""ResX"": "&_xlfn.TEXTBEFORE(_xlpm.v,"x")&", ""ResY"": "&_xlfn.TEXTAFTER(_xlpm.v,"x")&"}"))),_xlpm.vfc,_xlfn.GROUPBY(TRANSPOSE(_xlpm.crop),TRANSPOSE(_xlpm.vf),_xlfn.LAMBDA(_xlpm.v,_xlfn.TEXTJOIN(", ",TRUE,_xlpm.v)),0,0),_xlpm.vfcc,_xlfn.BYROW(_xlpm.vfc,_xlfn.LAMBDA(_xlpm.r,IF(INDEX(_xlpm.r,1,2)="","","{""Crop"": """&INDEX(_xlpm.r,1,1)&""", ""Subs"": {"&INDEX(_xlpm.r,1,2)&"}}"))),_xlpm.vs,_xlfn.SORTBY(_xlpm.vfcc,MATCH(INDEX(_xlpm.vfc,0,1),_xlpm.crop,0)),"""CropSubSampling"": ["&_xlfn.TEXTJOIN(", ",TRUE,_xlpm.vs)&"]")} -> "CropSubSampling": [{"Crop": "FX", "Subs": {"Size L": {"ResX": 6016, "ResY": 4016}, "Size M": {"ResX": 4512, "ResY": 3008}, "Size S": {"ResX": 3008, "ResY": 2008}}}, {"Crop": "DX", "Subs": {"Size L": {"ResX": 3936, "ResY": 2624}, "Size M": {"ResX": 2944, "ResY": 1968}, "Size S": {"ResX": 1968, "ResY": 1312}}}]
A22: D700 | B22: D700 | C22: 2008 | D22: EXPEED | F22: Nikon NC81338L | G22: CMOS | I22: 14 | J22: 4256 | K22: 2832 | L22: 36 | M22: 23.9 | N22: 8.45 | O22: 8.45 | Q22: FX 0, DX 1 | R22: 4256x2832 | S22: 3184x2120 | T22: 2128x1416 | U22: 2784x1848 | V22: 2080x1384 | W22: 1392x920 | AQ22: =""""&B22&""": {"&"""Name"": "&""""&A22&""", "&"""Year"": "&C22&", "&"""Processor"": "&""""&D22&""", "&"""Sensor"": {"&"""Name"": "&""""&F22&""", "&"""Type"": "&""""&G22&""", "&"""Bayer"": "&""""&H22&""", "&"""BitDepth"": "&""&I22&", "&"""ResX"": "&""&J22&", "&"""ResY"": "&""&K22&", "&"""SizeX"": "&""&SUBSTITUTE(L22,",",".")&", "&"""SizeY"": "&""&SUBSTITUTE(M22,",",".")&", "&"""PixelSizeX"": "&""&SUBSTITUTE(N22,",",".")&", "&"""PixelSizeY"": "&""&SUBSTITUTE(O22,",",".")&"}, "&AR22&"}" -> "D700": {"Name": "D700", "Year": 2008, "Processor": "EXPEED", "Sensor": {"Name": "Nikon NC81338L", "Type": "CMOS", "Bayer": "", "BitDepth": 14, "ResX": 4256, "ResY": 2832, "SizeX": 36, "SizeY": 23.9, "PixelSizeX": 8.45, "PixelSizeY": 8.45}, "CropSubSampling": [{"Crop": "FX", "Subs": {"Size L": {"ResX": 4256, "ResY": 2832}, "Size M": {"ResX": 3184, "ResY": 2120}, "Size S": {"ResX": 2128, "ResY": 1416}}}, {"Crop": "DX", "Subs": {"Size L": {"ResX": 2784, "ResY": 1848}, "Size M": {"ResX": 2080, "ResY": 1384}, "Size S": {"ResX": 1392, "ResY": 920}}}]} | AR22: {=_xlfn.LET(_xlpm.crop,$R$2:$AO$2,_xlpm.size,$R$3:$AO$3,_xlpm.value,R22:AO22,_xlpm.vf,_xlfn.MAP(_xlpm.size,_xlpm.value,_xlfn.LAMBDA(_xlpm.s,_xlpm.v,IF(_xlpm.v="","",""""&_xlpm.s&""": {""ResX"": "&_xlfn.TEXTBEFORE(_xlpm.v,"x")&", ""ResY"": "&_xlfn.TEXTAFTER(_xlpm.v,"x")&"}"))),_xlpm.vfc,_xlfn.GROUPBY(TRANSPOSE(_xlpm.crop),TRANSPOSE(_xlpm.vf),_xlfn.LAMBDA(_xlpm.v,_xlfn.TEXTJOIN(", ",TRUE,_xlpm.v)),0,0),_xlpm.vfcc,_xlfn.BYROW(_xlpm.vfc,_xlfn.LAMBDA(_xlpm.r,IF(INDEX(_xlpm.r,1,2)="","","{""Crop"": """&INDEX(_xlpm.r,1,1)&""", ""Subs"": {"&INDEX(_xlpm.r,1,2)&"}}"))),_xlpm.vs,_xlfn.SORTBY(_xlpm.vfcc,MATCH(INDEX(_xlpm.vfc,0,1),_xlpm.crop,0)),"""CropSubSampling"": ["&_xlfn.TEXTJOIN(", ",TRUE,_xlpm.vs)&"]")} -> "CropSubSampling": [{"Crop": "FX", "Subs": {"Size L": {"ResX": 4256, "ResY": 2832}, "Size M": {"ResX": 3184, "ResY": 2120}, "Size S": {"ResX": 2128, "ResY": 1416}}}, {"Crop": "DX", "Subs": {"Size L": {"ResX": 2784, "ResY": 1848}, "Size M": {"ResX": 2080, "ResY": 1384}, "Size S": {"ResX": 1392, "ResY": 920}}}]
A23: D750 | B23: D750 | C23: 2014 | D23: EXPEED 4 | F23: Sony IMX-128- (L) -AQP | G23: CMOS | I23: 14 | J23: 6016 | K23: 4016 | L23: 35.9 | M23: 24 | N23: 5.97 | O23: 5.97 | Q23: FX 0, DX 1, 1.2x 3 | R23: 6016x4016 | S23: 4512x3008 | T23: 3008x2008 | U23: 3936x2624 | V23: 2944x1968 | W23: 1968x1312 | AG23: 5008x3336 | AH23: 3752x2504 | AI23: 2504x1664 | AQ23: =""""&B23&""": {"&"""Name"": "&""""&A23&""", "&"""Year"": "&C23&", "&"""Processor"": "&""""&D23&""", "&"""Sensor"": {"&"""Name"": "&""""&F23&""", "&"""Type"": "&""""&G23&""", "&"""Bayer"": "&""""&H23&""", "&"""BitDepth"": "&""&I23&", "&"""ResX"": "&""&J23&", "&"""ResY"": "&""&K23&", "&"""SizeX"": "&""&SUBSTITUTE(L23,",",".")&", "&"""SizeY"": "&""&SUBSTITUTE(M23,",",".")&", "&"""PixelSizeX"": "&""&SUBSTITUTE(N23,",",".")&", "&"""PixelSizeY"": "&""&SUBSTITUTE(O23,",",".")&"}, "&AR23&"}" -> "D750": {"Name": "D750", "Year": 2014, "Processor": "EXPEED 4", "Sensor": {"Name": "Sony IMX-128- (L) -AQP", "Type": "CMOS", "Bayer": "", "BitDepth": 14, "ResX": 6016, "ResY": 4016, "SizeX": 35.9, "SizeY": 24, "PixelSizeX": 5.97, "PixelSizeY": 5.97}, "CropSubSampling": [{"Crop": "FX", "Subs": {"Size L": {"ResX": 6016, "ResY": 4016}, "Size M": {"ResX": 4512, "ResY": 3008}, "Size S": {"ResX": 3008, "ResY": 2008}}}, {"Crop": "DX", "Subs": {"Size L": {"ResX": 3936, "ResY": 2624}, "Size M": {"ResX": 2944, "ResY": 1968}, "Size S": {"ResX": 1968, "ResY": 1312}}}, {"Crop": "1.2x", "Subs": {"Size L": {"ResX": 5008, "ResY": 3336}, "Size M": {"ResX": 3752, "ResY": 2504}, "Size S": {"ResX": 2504, "ResY": 1664}}}]} | AR23: {=_xlfn.LET(_xlpm.crop,$R$2:$AO$2,_xlpm.size,$R$3:$AO$3,_xlpm.value,R23:AO23,_xlpm.vf,_xlfn.MAP(_xlpm.size,_xlpm.value,_xlfn.LAMBDA(_xlpm.s,_xlpm.v,IF(_xlpm.v="","",""""&_xlpm.s&""": {""ResX"": "&_xlfn.TEXTBEFORE(_xlpm.v,"x")&", ""ResY"": "&_xlfn.TEXTAFTER(_xlpm.v,"x")&"}"))),_xlpm.vfc,_xlfn.GROUPBY(TRANSPOSE(_xlpm.crop),TRANSPOSE(_xlpm.vf),_xlfn.LAMBDA(_xlpm.v,_xlfn.TEXTJOIN(", ",TRUE,_xlpm.v)),0,0),_xlpm.vfcc,_xlfn.BYROW(_xlpm.vfc,_xlfn.LAMBDA(_xlpm.r,IF(INDEX(_xlpm.r,1,2)="","","{""Crop"": """&INDEX(_xlpm.r,1,1)&""", ""Subs"": {"&INDEX(_xlpm.r,1,2)&"}}"))),_xlpm.vs,_xlfn.SORTBY(_xlpm.vfcc,MATCH(INDEX(_xlpm.vfc,0,1),_xlpm.crop,0)),"""CropSubSampling"": ["&_xlfn.TEXTJOIN(", ",TRUE,_xlpm.vs)&"]")} -> "CropSubSampling": [{"Crop": "FX", "Subs": {"Size L": {"ResX": 6016, "ResY": 4016}, "Size M": {"ResX": 4512, "ResY": 3008}, "Size S": {"ResX": 3008, "ResY": 2008}}}, {"Crop": "DX", "Subs": {"Size L": {"ResX": 3936, "ResY": 2624}, "Size M": {"ResX": 2944, "ResY": 1968}, "Size S": {"ResX": 1968, "ResY": 1312}}}, {"Crop": "1.2x", "Subs": {"Size L": {"ResX": 5008, "ResY": 3336}, "Size M": {"ResX": 3752, "ResY": 2504}, "Size S": {"ResX": 2504, "ResY": 1664}}}]
A24: D780 | B24: D780 | C24: 2020 | D24: EXPEED 6 | F24: Sony ? | G24: BSI-CMOS | I24: 14 | J24: 6048 | K24: 4024 | L24: 35.9 | M24: 23.9 | N24: 5.94 | O24: 5.94 | Q24: FX 0, DX 2, 1:1 4, 16:9 5 | R24: 6048x4024 | S24: 4528x3016 | T24: 3024x2016 | U24: 3936x2624 | V24: 2944x1968 | W24: 1968x1312 | AJ24: 4016x4016 | AK24: 3008x3008 | AL24: 2000x2000 | AM24: 6048x3400 | AN24: 4528x2544 | AO24: 3024x1696 | AQ24: =""""&B24&""": {"&"""Name"": "&""""&A24&""", "&"""Year"": "&C24&", "&"""Processor"": "&""""&D24&""", "&"""Sensor"": {"&"""Name"": "&""""&F24&""", "&"""Type"": "&""""&G24&""", "&"""Bayer"": "&""""&H24&""", "&"""BitDepth"": "&""&I24&", "&"""ResX"": "&""&J24&", "&"""ResY"": "&""&K24&", "&"""SizeX"": "&""&SUBSTITUTE(L24,",",".")&", "&"""SizeY"": "&""&SUBSTITUTE(M24,",",".")&", "&"""PixelSizeX"": "&""&SUBSTITUTE(N24,",",".")&", "&"""PixelSizeY"": "&""&SUBSTITUTE(O24,",",".")&"}, "&AR24&"}" -> "D780": {"Name": "D780", "Year": 2020, "Processor": "EXPEED 6", "Sensor": {"Name": "Sony ?", "Type": "BSI-CMOS", "Bayer": "", "BitDepth": 14, "ResX": 6048, "ResY": 4024, "SizeX": 35.9, "SizeY": 23.9, "PixelSizeX": 5.94, "PixelSizeY": 5.94}, "CropSubSampling": [{"Crop": "FX", "Subs": {"Size L": {"ResX": 6048, "ResY": 4024}, "Size M": {"ResX": 4528, "ResY": 3016}, "Size S": {"ResX": 3024, "ResY": 2016}}}, {"Crop": "DX", "Subs": {"Size L": {"ResX": 3936, "ResY": 2624}, "Size M": {"ResX": 2944, "ResY": 1968}, "Size S": {"ResX": 1968, "ResY": 1312}}}, {"Crop": "1:1", "Subs": {"Size L": {"ResX": 4016, "ResY": 4016}, "Size M": {"ResX": 3008, "ResY": 3008}, "Size S": {"ResX": 2000, "ResY": 2000}}}, {"Crop": "16:9", "Subs": {"Size L": {"ResX": 6048, "ResY": 3400}, "Size M": {"ResX": 4528, "ResY": 2544}, "Size S": {"ResX": 3024, "ResY": 1696}}}]} | AR24: {=_xlfn.LET(_xlpm.crop,$R$2:$AO$2,_xlpm.size,$R$3:$AO$3,_xlpm.value,R24:AO24,_xlpm.vf,_xlfn.MAP(_xlpm.size,_xlpm.value,_xlfn.LAMBDA(_xlpm.s,_xlpm.v,IF(_xlpm.v="","",""""&_xlpm.s&""": {""ResX"": "&_xlfn.TEXTBEFORE(_xlpm.v,"x")&", ""ResY"": "&_xlfn.TEXTAFTER(_xlpm.v,"x")&"}"))),_xlpm.vfc,_xlfn.GROUPBY(TRANSPOSE(_xlpm.crop),TRANSPOSE(_xlpm.vf),_xlfn.LAMBDA(_xlpm.v,_xlfn.TEXTJOIN(", ",TRUE,_xlpm.v)),0,0),_xlpm.vfcc,_xlfn.BYROW(_xlpm.vfc,_xlfn.LAMBDA(_xlpm.r,IF(INDEX(_xlpm.r,1,2)="","","{""Crop"": """&INDEX(_xlpm.r,1,1)&""", ""Subs"": {"&INDEX(_xlpm.r,1,2)&"}}"))),_xlpm.vs,_xlfn.SORTBY(_xlpm.vfcc,MATCH(INDEX(_xlpm.vfc,0,1),_xlpm.crop,0)),"""CropSubSampling"": ["&_xlfn.TEXTJOIN(", ",TRUE,_xlpm.vs)&"]")} -> "CropSubSampling": [{"Crop": "FX", "Subs": {"Size L": {"ResX": 6048, "ResY": 4024}, "Size M": {"ResX": 4528, "ResY": 3016}, "Size S": {"ResX": 3024, "ResY": 2016}}}, {"Crop": "DX", "Subs": {"Size L": {"ResX": 3936, "ResY": 2624}, "Size M": {"ResX": 2944, "ResY": 1968}, "Size S": {"ResX": 1968, "ResY": 1312}}}, {"Crop": "1:1", "Subs": {"Size L": {"ResX": 4016, "ResY": 4016}, "Size M": {"ResX": 3008, "ResY": 3008}, "Size S": {"ResX": 2000, "ResY": 2000}}}, {"Crop": "16:9", "Subs": {"Size L": {"ResX": 6048, "ResY": 3400}, "Size M": {"ResX": 4528, "ResY": 2544}, "Size S": {"ResX": 3024, "ResY": 1696}}}]
A25: D800 | B25: D800 | C25: 2012 | D25: EXPEED 3 | F25: Sony IMX-094-AQP | G25: CMOS | I25: 14 | J25: 7360 | K25: 4912 | L25: 35.9 | M25: 24 | N25: 4.88 | O25: 4.88 | Q25: FX 0, DX 1, 5:4 2, 1.2x 3 | R25: 7360x4912 | S25: 5520x3680 | T25: 3680x2456 | U25: 4800x3200 | V25: 3600x2400 | W25: 2400x1600 | AD25: 6144x4912 | AE25: 4608x3680 | AF25: 3072x2456 | AG25: 6144x4080 | AH25: 4608x3056 | AI25: 3072x2040 | AQ25: =""""&B25&""": {"&"""Name"": "&""""&A25&""", "&"""Year"": "&C25&", "&"""Processor"": "&""""&D25&""", "&"""Sensor"": {"&"""Name"": "&""""&F25&""", "&"""Type"": "&""""&G25&""", "&"""Bayer"": "&""""&H25&""", "&"""BitDepth"": "&""&I25&", "&"""ResX"": "&""&J25&", "&"""ResY"": "&""&K25&", "&"""SizeX"": "&""&SUBSTITUTE(L25,",",".")&", "&"""SizeY"": "&""&SUBSTITUTE(M25,",",".")&", "&"""PixelSizeX"": "&""&SUBSTITUTE(N25,",",".")&", "&"""PixelSizeY"": "&""&SUBSTITUTE(O25,",",".")&"}, "&AR25&"}" -> "D800": {"Name": "D800", "Year": 2012, "Processor": "EXPEED 3", "Sensor": {"Name": "Sony IMX-094-AQP", "Type": "CMOS", "Bayer": "", "BitDepth": 14, "ResX": 7360, "ResY": 4912, "SizeX": 35.9, "SizeY": 24, "PixelSizeX": 4.88, "PixelSizeY": 4.88}, "CropSubSampling": [{"Crop": "FX", "Subs": {"Size L": {"ResX": 7360, "ResY": 4912}, "Size M": {"ResX": 5520, "ResY": 3680}, "Size S": {"ResX": 3680, "ResY": 2456}}}, {"Crop": "DX", "Subs": {"Size L": {"ResX": 4800, "ResY": 3200}, "Size M": {"ResX": 3600, "ResY": 2400}, "Size S": {"ResX": 2400, "ResY": 1600}}}, {"Crop": "5:4", "Subs": {"Size L": {"ResX": 6144, "ResY": 4912}, "Size M": {"ResX": 4608, "ResY": 3680}, "Size S": {"ResX": 3072, "ResY": 2456}}}, {"Crop": "1.2x", "Subs": {"Size L": {"ResX": 6144, "ResY": 4080}, "Size M": {"ResX": 4608, "ResY": 3056}, "Size S": {"ResX": 3072, "ResY": 2040}}}]} | AR25: {=_xlfn.LET(_xlpm.crop,$R$2:$AO$2,_xlpm.size,$R$3:$AO$3,_xlpm.value,R25:AO25,_xlpm.vf,_xlfn.MAP(_xlpm.size,_xlpm.value,_xlfn.LAMBDA(_xlpm.s,_xlpm.v,IF(_xlpm.v="","",""""&_xlpm.s&""": {""ResX"": "&_xlfn.TEXTBEFORE(_xlpm.v,"x")&", ""ResY"": "&_xlfn.TEXTAFTER(_xlpm.v,"x")&"}"))),_xlpm.vfc,_xlfn.GROUPBY(TRANSPOSE(_xlpm.crop),TRANSPOSE(_xlpm.vf),_xlfn.LAMBDA(_xlpm.v,_xlfn.TEXTJOIN(", ",TRUE,_xlpm.v)),0,0),_xlpm.vfcc,_xlfn.BYROW(_xlpm.vfc,_xlfn.LAMBDA(_xlpm.r,IF(INDEX(_xlpm.r,1,2)="","","{""Crop"": """&INDEX(_xlpm.r,1,1)&""", ""Subs"": {"&INDEX(_xlpm.r,1,2)&"}}"))),_xlpm.vs,_xlfn.SORTBY(_xlpm.vfcc,MATCH(INDEX(_xlpm.vfc,0,1),_xlpm.crop,0)),"""CropSubSampling"": ["&_xlfn.TEXTJOIN(", ",TRUE,_xlpm.vs)&"]")} -> "CropSubSampling": [{"Crop": "FX", "Subs": {"Size L": {"ResX": 7360, "ResY": 4912}, "Size M": {"ResX": 5520, "ResY": 3680}, "Size S": {"ResX": 3680, "ResY": 2456}}}, {"Crop": "DX", "Subs": {"Size L": {"ResX": 4800, "ResY": 3200}, "Size M": {"ResX": 3600, "ResY": 2400}, "Size S": {"ResX": 2400, "ResY": 1600}}}, {"Crop": "5:4", "Subs": {"Size L": {"ResX": 6144, "ResY": 4912}, "Size M": {"ResX": 4608, "ResY": 3680}, "Size S": {"ResX": 3072, "ResY": 2456}}}, {"Crop": "1.2x", "Subs": {"Size L": {"ResX": 6144, "ResY": 4080}, "Size M": {"ResX": 4608, "ResY": 3056}, "Size S": {"ResX": 3072, "ResY": 2040}}}]
A26: D800E | B26: D800E | C26: 2012 | D26: EXPEED 3 | F26: Sony IMX-094-AQP | G26: CMOS (Without AA filter) | I26: 14 | J26: 7360 | K26: 4912 | L26: 35.9 | M26: 24 | N26: 4.88 | O26: 4.88 | Q26: FX 0, DX 1, 5:4 2, 1.2x 3 | R26: 7360x4912 | S26: 5520x3680 | T26: 3680x2456 | U26: 4800x3200 | V26: 3600x2400 | W26: 2400x1600 | AD26: 6144x4912 | AE26: 4608x3680 | AF26: 3072x2456 | AG26: 6144x4080 | AH26: 4608x3056 | AI26: 3072x2040 | AQ26: =""""&B26&""": {"&"""Name"": "&""""&A26&""", "&"""Year"": "&C26&", "&"""Processor"": "&""""&D26&""", "&"""Sensor"": {"&"""Name"": "&""""&F26&""", "&"""Type"": "&""""&G26&""", "&"""Bayer"": "&""""&H26&""", "&"""BitDepth"": "&""&I26&", "&"""ResX"": "&""&J26&", "&"""ResY"": "&""&K26&", "&"""SizeX"": "&""&SUBSTITUTE(L26,",",".")&", "&"""SizeY"": "&""&SUBSTITUTE(M26,",",".")&", "&"""PixelSizeX"": "&""&SUBSTITUTE(N26,",",".")&", "&"""PixelSizeY"": "&""&SUBSTITUTE(O26,",",".")&"}, "&AR26&"}" -> "D800E": {"Name": "D800E", "Year": 2012, "Processor": "EXPEED 3", "Sensor": {"Name": "Sony IMX-094-AQP", "Type": "CMOS (Without AA filter)", "Bayer": "", "BitDepth": 14, "ResX": 7360, "ResY": 4912, "SizeX": 35.9, "SizeY": 24, "PixelSizeX": 4.88, "PixelSizeY": 4.88}, "CropSubSampling": [{"Crop": "FX", "Subs": {"Size L": {"ResX": 7360, "ResY": 4912}, "Size M": {"ResX": 5520, "ResY": 3680}, "Size S": {"ResX": 3680, "ResY": 2456}}}, {"Crop": "DX", "Subs": {"Size L": {"ResX": 4800, "ResY": 3200}, "Size M": {"ResX": 3600, "ResY": 2400}, "Size S": {"ResX": 2400, "ResY": 1600}}}, {"Crop": "5:4", "Subs": {"Size L": {"ResX": 6144, "ResY": 4912}, "Size M": {"ResX": 4608, "ResY": 3680}, "Size S": {"ResX": 3072, "ResY": 2456}}}, {"Crop": "1.2x", "Subs": {"Size L": {"ResX": 6144, "ResY": 4080}, "Size M": {"ResX": 4608, "ResY": 3056}, "Size S": {"ResX": 3072, "ResY": 2040}}}]} | AR26: {=_xlfn.LET(_xlpm.crop,$R$2:$AO$2,_xlpm.size,$R$3:$AO$3,_xlpm.value,R26:AO26,_xlpm.vf,_xlfn.MAP(_xlpm.size,_xlpm.value,_xlfn.LAMBDA(_xlpm.s,_xlpm.v,IF(_xlpm.v="","",""""&_xlpm.s&""": {""ResX"": "&_xlfn.TEXTBEFORE(_xlpm.v,"x")&", ""ResY"": "&_xlfn.TEXTAFTER(_xlpm.v,"x")&"}"))),_xlpm.vfc,_xlfn.GROUPBY(TRANSPOSE(_xlpm.crop),TRANSPOSE(_xlpm.vf),_xlfn.LAMBDA(_xlpm.v,_xlfn.TEXTJOIN(", ",TRUE,_xlpm.v)),0,0),_xlpm.vfcc,_xlfn.BYROW(_xlpm.vfc,_xlfn.LAMBDA(_xlpm.r,IF(INDEX(_xlpm.r,1,2)="","","{""Crop"": """&INDEX(_xlpm.r,1,1)&""", ""Subs"": {"&INDEX(_xlpm.r,1,2)&"}}"))),_xlpm.vs,_xlfn.SORTBY(_xlpm.vfcc,MATCH(INDEX(_xlpm.vfc,0,1),_xlpm.crop,0)),"""CropSubSampling"": ["&_xlfn.TEXTJOIN(", ",TRUE,_xlpm.vs)&"]")} -> "CropSubSampling": [{"Crop": "FX", "Subs": {"Size L": {"ResX": 7360, "ResY": 4912}, "Size M": {"ResX": 5520, "ResY": 3680}, "Size S": {"ResX": 3680, "ResY": 2456}}}, {"Crop": "DX", "Subs": {"Size L": {"ResX": 4800, "ResY": 3200}, "Size M": {"ResX": 3600, "ResY": 2400}, "Size S": {"ResX": 2400, "ResY": 1600}}}, {"Crop": "5:4", "Subs": {"Size L": {"ResX": 6144, "ResY": 4912}, "Size M": {"ResX": 4608, "ResY": 3680}, "Size S": {"ResX": 3072, "ResY": 2456}}}, {"Crop": "1.2x", "Subs": {"Size L": {"ResX": 6144, "ResY": 4080}, "Size M": {"ResX": 4608, "ResY": 3056}, "Size S": {"ResX": 3072, "ResY": 2040}}}]
